<?xml version="1.0" ?>
<!-- =================================================================================== -->
<!-- |    This document was autogenerated by xacro from dumbo_2grippers.urdf.xacro     | -->
<!-- |    EDITING THIS FILE BY HAND IS NOT RECOMMENDED                                 | -->
<!-- =================================================================================== -->
<robot name="dumbo" xmlns:controller="http://playerstage.sourceforge.net/gazebo/xmlschema/#controller" xmlns:interface="http://playerstage.sourceforge.net/gazebo/xmlschema/#interface" xmlns:sensor="http://playerstage.sourceforge.net/gazebo/xmlschema/#sensor" xmlns:xacro="http://ros.org/wiki/xacro">
  <!-- This version incorporates Schunk PG70 parallel gripper -->
  <!-- common stuff -->
  <material name="Grey">
    <color rgba="0.7 0.7 0.7 1.0"/>
  </material>
  <material name="Grey2">
    <color rgba="0.9 0.9 0.9 1.0"/>
  </material>
  <material name="Black">
    <color rgba="0.0 0.0 0.0 1.0"/>
  </material>
  <material name="Yellow">
    <color rgba="1 1 0 1"/>
  </material>
  <material name="Blue">
    <color rgba="0.0 0.0 0.8 1.0"/>
  </material>
  <material name="Green">
    <color rgba="0.0 0.8 0.0 1.0"/>
  </material>
  <material name="IPA/DarkGrey">
    <color rgba="0.7 0.7 0.7 1.0"/>
  </material>
  <material name="IPA/LightGrey">
    <color rgba="0.81 0.81 0.81 1.0"/>
  </material>
  <material name="Red">
    <color rgba="0.8 0.0 0.0 1.0"/>
  </material>
  <material name="White">
    <color rgba="1.0 1.0 1.0 1.0"/>
  </material>
  <material name="IPA/Black">
    <color rgba="0.0 0.0 0.0 1.0"/>
  </material>
  <material name="IPA/Orange">
    <color rgba="1.0 0.5 0.0 1.0"/>
  </material>
  <material name="Schunk/DarkGolden">
    <color rgba="0.72 0.5255 0.043 1.0"/>
  </material>
  <material name="Caster">
    <texture filename="package://pr2_ogre/Media/materials/textures/pr2_caster_texture.png"/>
  </material>
  <material name="Wheel_l">
    <texture filename="package://pr2_ogre/Media/materials/textures/pr2_wheel_left.png"/>
  </material>
  <material name="Wheel_r">
    <texture filename="package://pr2_ogre/Media/materials/textures/pr2_wheel_right.png"/>
  </material>
  <material name="RollLinks">
    <texture filename="package://pr2_ogre/Media/materials/textures/pr2_wheel_left.png"/>
  </material>
  <!-- The following included files set up definitions of parts of the robot body -->
  <!-- Platform -->
  <link name="base_link">
    <!-- <inertial> -->
    <!--   <mass value="20.0" /> -->
    <!-- 	<origin xyz = "0.0 0.0 0.0" rpy="0.0 0.0 0.0" /> -->
    <!--   <inertia ixx="1.0" ixy="0.0" ixz="0.0" -->
    <!--            iyy="1.0" iyz="0.0" izz="1.0" /> -->
    <!-- </inertial> -->
    <visual>
      <origin rpy="1.57079632679 0.0 -1.57079632679" xyz="0.0 0.0 0.0"/>
      <geometry>
        <mesh filename="package://dumbo_description/meshes/platform/powerbot.ply"/>
      </geometry>
    </visual>
    <collision name="base_collision">
      <origin rpy="0.0 0.0 0.0" xyz="0.0 -0.07 0.275"/>
      <geometry>
        <box size="0.7 0.9 0.45"/>
      </geometry>
    </collision>
  </link>
  <!-- Torso -->
  <joint name="torso_joint" type="fixed">
    <origin rpy="0.0 0.0 0.0" xyz="0.0 0.06 0.696"/>
    <parent link="base_link"/>
    <child link="torso_link"/>
  </joint>
  <link name="torso_link">
    <inertial>
      <mass value="20.0"/>
      <origin rpy="0.0 0.0 0.0" xyz="0.0 0.0 0.0"/>
      <inertia ixx="3.0" ixy="0.0" ixz="0.0" iyy="3.0" iyz="0.0" izz="1.0"/>
    </inertial>
    <visual>
      <origin rpy="0.0 0.0 0.0" xyz="0.0 0.0 0.0"/>
      <geometry>
        <cylinder length="0.445" radius="0.12"/>
      </geometry>
      <material name="Black"/>
    </visual>
    <collision name="torso_collision">
      <origin rpy="0.0 0.0 0.0" xyz="0.0 0.0 0.09"/>
      <geometry>
        <box size="0.24 0.24 0.625"/>
      </geometry>
    </collision>
  </link>
  <joint name="torso_middle_plate_joint" type="fixed">
    <origin rpy="0.0 0.0 0.0" xyz="0.0 0.0 0.3125"/>
    <parent link="torso_link"/>
    <child link="torso_middle_plate_link"/>
  </joint>
  <link name="torso_middle_plate_link">
    <inertial>
      <mass value="20.0"/>
      <origin rpy="0.0 0.0 0.0" xyz="0.0 0.0 0.0"/>
      <inertia ixx="1.0" ixy="0.0" ixz="0.0" iyy="2.0" iyz="0.0" izz="0.5"/>
    </inertial>
    <visual>
      <origin rpy="0.0 0.0 0.0" xyz="0.0 0.0 0.0"/>
      <geometry>
        <box size="0.003 0.188 0.18"/>
      </geometry>
      <material name="Grey"/>
    </visual>
    <collision name="torso_middle_plate_collision">
      <origin rpy="0.0 0.0 0.0" xyz="0.0 0.0 0.0"/>
      <geometry>
        <box size="0.003 0.188 0.18"/>
      </geometry>
    </collision>
  </link>
  <joint name="torso_top_plate_joint" type="fixed">
    <origin rpy="0.0 0.0 0.0" xyz="0.0 0.0 0.0915"/>
    <parent link="torso_middle_plate_link"/>
    <child link="torso_top_plate_link"/>
  </joint>
  <link name="torso_top_plate_link">
    <inertial>
      <mass value="20.0"/>
      <origin rpy="0.0 0.0 0.0" xyz="0.0 0.0 0.0"/>
      <inertia ixx="1.0" ixy="0.0" ixz="0.0" iyy="2.0" iyz="0.0" izz="0.5"/>
    </inertial>
    <visual>
      <origin rpy="0.0 0.0 0.0" xyz="0.0 0.0 0.0"/>
      <geometry>
        <box size="0.1 0.188 0.003"/>
      </geometry>
      <material name="Black"/>
    </visual>
    <collision name="torso_top_plate_collision">
      <origin rpy="0.0 0.0 0.0" xyz="0.0 0.0 0.0"/>
      <geometry>
        <box size="0.1 0.188 0.003"/>
      </geometry>
    </collision>
  </link>
  <joint name="torso_front_plate_joint" type="fixed">
    <origin rpy="0.0 0.0 0.0" xyz="0.0 0.094 0.0"/>
    <parent link="torso_middle_plate_link"/>
    <child link="torso_front_plate_link"/>
  </joint>
  <link name="torso_front_plate_link">
    <inertial>
      <mass value="20.0"/>
      <origin rpy="0.0 0.0 0.0" xyz="0.0 0.0 0.0"/>
      <inertia ixx="1.0" ixy="0.0" ixz="0.0" iyy="2.0" iyz="0.0" izz="0.5"/>
    </inertial>
    <visual>
      <origin rpy="0.0 0.0 0.0" xyz="0.0 0.0 0.0"/>
      <geometry>
        <box size="0.1 0.003 0.18"/>
      </geometry>
      <material name="Black"/>
    </visual>
    <collision name="torso_front_plate_collision">
      <origin rpy="0.0 0.0 0.0" xyz="0.0 0.0 0.0"/>
      <geometry>
        <box size="0.1 0.003 0.18"/>
      </geometry>
    </collision>
  </link>
  <joint name="torso_back_plate_joint" type="fixed">
    <origin rpy="0.0 0.0 0.0" xyz="0.0 -0.094 0.0"/>
    <parent link="torso_middle_plate_link"/>
    <child link="torso_back_plate_link"/>
  </joint>
  <link name="torso_back_plate_link">
    <inertial>
      <mass value="20.0"/>
      <origin rpy="0.0 0.0 0.0" xyz="0.0 0.0 0.0"/>
      <inertia ixx="1.0" ixy="0.0" ixz="0.0" iyy="2.0" iyz="0.0" izz="0.5"/>
    </inertial>
    <visual>
      <origin rpy="0.0 0.0 0.0" xyz="0.0 0.0 0.0"/>
      <geometry>
        <box size="0.1 0.003 0.18"/>
      </geometry>
      <material name="Black"/>
    </visual>
    <collision name="torso_back_plate_collision">
      <origin rpy="0.0 0.0 0.0" xyz="0.0 0.0 0.0"/>
      <geometry>
        <box size="0.1 0.003 0.18"/>
      </geometry>
    </collision>
  </link>
  <joint name="arm_base_joint" type="fixed">
    <origin rpy="0.0 0.0 0.0" xyz="0.0 0.0 0.0"/>
    <parent link="torso_middle_plate_link"/>
    <child link="arm_base_link"/>
  </joint>
  <link name="arm_base_link">
    <visual>
      <origin rpy="0.0 0.0 0.0" xyz="0.0 0.0 0.0"/>
      <geometry>
        <box size="0.003 0.188 0.18"/>
      </geometry>
    </visual>
  </link>
  <!-- Accelerometer -->
  <joint name="accelerometer_joint" type="fixed">
    <origin rpy="-1.5452 -0.0353 0.0295" xyz="0.0 -0.098 0.0"/>
    <parent link="arm_base_link"/>
    <child link="accelerometer"/>
  </joint>
  <link name="accelerometer">
    <inertial>
      <origin rpy="0.0 0.0 0.0" xyz="0.0 0.0 0.0"/>
      <mass value="1.0"/>
      <inertia ixx="0.01" ixy="0" ixz="0" iyy="0.01" iyz="0" izz="0.01"/>
    </inertial>
    <visual>
      <origin rpy="0.0 0.0 0.0" xyz="0.0 0.0 0.0"/>
      <geometry>
        <box rpy="0.0 0.0 0.0" size="0.1 0.1 0.005"/>
      </geometry>
      <material name="Grey"/>
    </visual>
    <collision>
      <origin rpy="0.0 0.0 0.0" xyz="0.0 0.0 0.0"/>
      <geometry>
        <box rpy="0.0 0.0 0.0" size="0.1 0.1 0.005"/>
      </geometry>
    </collision>
  </link>
  <!-- Schunk LWA -->
  <joint name="right_arm_0_joint" type="fixed">
    <origin rpy="1.57079632679 0.0 1.57079632679" xyz="0.268 0.0 0.0"/>
    <parent link="arm_base_link"/>
    <child link="right_arm_0_link"/>
  </joint>
  <link name="right_arm_0_link">
    <inertial>
      <origin rpy="0 0 0" xyz="0 0 0"/>
      <mass value="1.0"/>
      <inertia ixx="0.01" ixy="0" ixz="0" iyy="0.01" iyz="0" izz="0.01"/>
    </inertial>
    <visual>
      <origin rpy="0 0 0" xyz="0 0 0"/>
      <geometry>
        <cylinder length="0.0001" radius="0.0001"/>
      </geometry>
    </visual>
  </link>
  <joint name="right_arm_1_joint" type="revolute">
    <origin rpy="0.0 0.0 0.0" xyz="0.0 0.0 0.0"/>
    <axis xyz="0 0 1"/>
    <calibration rising="0.0"/>
    <parent link="right_arm_0_link"/>
    <child link="right_arm_1_link"/>
    <limit effort="370" lower="-3.14159265359" upper="3.14159265359" velocity="0.523598775598"/>
    <safety_controller k_position="100" k_velocity="10" soft_lower_limit="-3.10668606855" soft_upper_limit="3.10668606855"/>
  </joint>
  <link name="right_arm_1_link">
    <inertial>
      <origin rpy="0.0 0.0 0.0" xyz="0 0 -0.15875"/>
      <mass value="1.0"/>
      <inertia ixx="0.01" ixy="0" ixz="0" iyy="0.01" iyz="0" izz="0.01"/>
    </inertial>
    <visual>
      <origin rpy="0.0 0.0 0.0" xyz="0 0 -0.15875"/>
      <geometry>
        <cylinder length="0.16" radius="0.051"/>
      </geometry>
      <material name="Yellow"/>
    </visual>
    <collision>
      <origin rpy="0 0 0" xyz="0 0 -0.13875"/>
      <geometry>
        <cylinder length="0.18" radius="0.071"/>
      </geometry>
    </collision>
  </link>
  <joint name="right_arm_2_joint" type="revolute">
    <origin rpy="-1.57079632679 3.14159265359 0.0" xyz="0.0 0.0 0.0"/>
    <axis xyz="0 0 1"/>
    <calibration rising="0.0"/>
    <parent link="right_arm_1_link"/>
    <child link="right_arm_2_link"/>
    <limit effort="370" lower="-2.09439510239" upper="2.09439510239" velocity="0.523598775598"/>
    <safety_controller k_position="100" k_velocity="10" soft_lower_limit="-2.05948851735" soft_upper_limit="2.05948851735"/>
  </joint>
  <link name="right_arm_2_link">
    <inertial>
      <origin rpy="0 0 0" xyz="0 0 0"/>
      <mass value="1.0"/>
      <inertia ixx="0.01" ixy="0" ixz="0" iyy="0.01" iyz="0" izz="0.01"/>
    </inertial>
    <visual>
      <origin rpy="0 0 0" xyz="0 0 0"/>
      <geometry>
        <cylinder length="0.16" radius="0.051"/>
      </geometry>
      <material name="Black"/>
    </visual>
    <collision>
      <origin rpy="0 0 0" xyz="0 0 0"/>
      <geometry>
        <cylinder length="0.18" radius="0.071"/>
      </geometry>
    </collision>
  </link>
  <joint name="right_arm_3_joint" type="revolute">
    <origin rpy="1.57079632679 0.0 3.14159265359" xyz="0.0 0.318 0.0"/>
    <axis xyz="0 0 1"/>
    <calibration rising="0.0"/>
    <parent link="right_arm_2_link"/>
    <child link="right_arm_3_link"/>
    <limit effort="370" lower="-3.14159265359" upper="3.14159265359" velocity="0.523598775598"/>
    <safety_controller k_position="100" k_velocity="10" soft_lower_limit="-3.10668606855" soft_upper_limit="3.10668606855"/>
  </joint>
  <link name="right_arm_3_link">
    <inertial>
      <origin rpy="0 0 0" xyz="0 0 -0.159"/>
      <mass value="1.0"/>
      <inertia ixx="0.01" ixy="0" ixz="0" iyy="0.01" iyz="0" izz="0.01"/>
    </inertial>
    <visual>
      <origin rpy="0 0 0" xyz="0 0 -0.159"/>
      <geometry>
        <cylinder length="0.16" radius="0.051"/>
      </geometry>
      <material name="Yellow"/>
    </visual>
    <collision>
      <origin rpy="0 0 0" xyz="0 0 -0.159"/>
      <geometry>
        <cylinder length="0.21" radius="0.071"/>
      </geometry>
    </collision>
  </link>
  <joint name="right_arm_4_joint" type="revolute">
    <origin rpy="-1.57079632679 3.14159265359 0.0" xyz="0.0 0.0 0.0"/>
    <axis xyz="0 0 1"/>
    <calibration rising="0.0"/>
    <parent link="right_arm_3_link"/>
    <child link="right_arm_4_link"/>
    <limit effort="370" lower="-2.09439510239" upper="2.09439510239" velocity="0.523598775598"/>
    <safety_controller k_position="100" k_velocity="10" soft_lower_limit="-2.05948851735" soft_upper_limit="2.05948851735"/>
  </joint>
  <link name="right_arm_4_link">
    <inertial>
      <origin rpy="0 0 0" xyz="0 0 0"/>
      <mass value="1.0"/>
      <inertia ixx="0.01" ixy="0" ixz="0" iyy="0.01" iyz="0" izz="0.01"/>
    </inertial>
    <visual>
      <origin rpy="0 0 0" xyz="0 0 0"/>
      <geometry>
        <cylinder length="0.16" radius="0.051"/>
      </geometry>
      <material name="Black"/>
    </visual>
    <collision>
      <origin rpy="0 0 0" xyz="0 0 0"/>
      <geometry>
        <cylinder length="0.18" radius="0.071"/>
      </geometry>
    </collision>
  </link>
  <joint name="right_arm_5_joint" type="revolute">
    <origin rpy="1.57079632679 0.0 3.14159265359" xyz="0.0 0.2765 0.0"/>
    <axis xyz="0 0 1"/>
    <calibration rising="0.0"/>
    <parent link="right_arm_4_link"/>
    <child link="right_arm_5_link"/>
    <limit effort="370" lower="-3.14159265359" upper="3.14159265359" velocity="0.523598775598"/>
    <safety_controller k_position="100" k_velocity="10" soft_lower_limit="-3.10668606855" soft_upper_limit="3.10668606855"/>
  </joint>
  <link name="right_arm_5_link">
    <inertial>
      <origin rpy="0 0 0" xyz="0 0 -0.13525"/>
      <mass value="1.0"/>
      <inertia ixx="0.01" ixy="0" ixz="0" iyy="0.01" iyz="0" izz="0.01"/>
    </inertial>
    <visual>
      <origin rpy="0 0 0" xyz="0 0 -0.13525"/>
      <geometry>
        <cylinder length="0.17" radius="0.045"/>
      </geometry>
      <material name="Yellow"/>
    </visual>
    <collision>
      <origin rpy="0 0 0" xyz="0 0 -0.13525"/>
      <geometry>
        <cylinder length="0.17" radius="0.065"/>
      </geometry>
    </collision>
  </link>
  <joint name="right_arm_6_joint" type="revolute">
    <origin rpy="-1.57079632679 3.14159265359 0.0" xyz="0.0 0.0 0.0"/>
    <axis xyz="0 0 1"/>
    <calibration rising="0.0"/>
    <parent link="right_arm_5_link"/>
    <child link="right_arm_6_link"/>
    <limit effort="370" lower="-1.95476876223" upper="1.95476876223" velocity="0.523598775598"/>
    <safety_controller k_position="100" k_velocity="10" soft_lower_limit="-1.91986217719" soft_upper_limit="1.91986217719"/>
  </joint>
  <link name="right_arm_6_link">
    <inertial>
      <origin rpy="0 0 0" xyz="0 0 0"/>
      <mass value="1.0"/>
      <inertia ixx="0.01" ixy="0" ixz="0" iyy="0.01" iyz="0" izz="0.01"/>
    </inertial>
    <visual>
      <origin rpy="0 0 0" xyz="0 0 0"/>
      <geometry>
        <cylinder length="0.17" radius="0.045"/>
      </geometry>
      <material name="Black"/>
    </visual>
    <collision>
      <origin rpy="0 0 0" xyz="0 0 0"/>
      <geometry>
        <cylinder length="0.19" radius="0.065"/>
      </geometry>
    </collision>
  </link>
  <joint name="right_arm_7_joint" type="revolute">
    <origin rpy="1.57079632679 0.0 3.14159265359" xyz="0.0 0.0 0.0"/>
    <axis xyz="0 0 1"/>
    <calibration rising="0.0"/>
    <parent link="right_arm_6_link"/>
    <child link="right_arm_7_link"/>
    <limit effort="370" lower="-3.14159265359" upper="3.14159265359" velocity="0.663225115758"/>
    <safety_controller k_position="100" k_velocity="10" soft_lower_limit="-3.10668606855" soft_upper_limit="3.10668606855"/>
  </joint>
  <link name="right_arm_7_link">
    <inertial>
      <origin rpy="0 0 0" xyz="0 0 0.148424"/>
      <mass value="1.0"/>
      <inertia ixx="0.01" ixy="0" ixz="0" iyy="0.01" iyz="0" izz="0.01"/>
    </inertial>
    <visual>
      <origin rpy="0 0 0" xyz="0 0 0.148424"/>
      <geometry>
        <cylinder length="0.17" radius="0.045"/>
      </geometry>
      <material name="Yellow"/>
    </visual>
    <collision>
      <origin rpy="0 0 0" xyz="0 0 0.148424"/>
      <geometry>
        <cylinder length="0.17" radius="0.065"/>
      </geometry>
    </collision>
  </link>
  <joint name="right_arm_FT_joint" type="fixed">
    <origin rpy="0.0 0.0 0.0" xyz="0.0 0.0 0.221348"/>
    <parent link="right_arm_7_link"/>
    <child link="right_arm_FT_sensor"/>
  </joint>
  <link name="right_arm_FT_sensor">
    <inertial>
      <origin rpy="0.0 0.0 0.0" xyz="0.0 0.0 0.0"/>
      <mass value="1.0"/>
      <inertia ixx="0.01" ixy="0" ixz="0" iyy="0.01" iyz="0" izz="0.01"/>
    </inertial>
    <visual>
      <origin rpy="0.0 0.0 0.0" xyz="0.0 0.0 0.03"/>
      <geometry>
        <cylinder length="0.03" radius="0.04"/>
      </geometry>
      <material name="Grey"/>
    </visual>
    <collision>
      <origin rpy="0.0 0.0 0.0" xyz="0.0 0.0 0.03"/>
      <geometry>
        <cylinder length="0.03" radius="0.065"/>
      </geometry>
    </collision>
  </link>
  <joint name="left_arm_0_joint" type="fixed">
    <origin rpy="1.57079632679 0.0 -1.57079632679" xyz="-0.268 0.0 0.0"/>
    <parent link="arm_base_link"/>
    <child link="left_arm_0_link"/>
  </joint>
  <link name="left_arm_0_link">
    <inertial>
      <origin rpy="0 0 0" xyz="0 0 0"/>
      <mass value="1.0"/>
      <inertia ixx="0.01" ixy="0" ixz="0" iyy="0.01" iyz="0" izz="0.01"/>
    </inertial>
    <visual>
      <origin rpy="0 0 0" xyz="0 0 0"/>
      <geometry>
        <cylinder length="0.0001" radius="0.0001"/>
      </geometry>
    </visual>
  </link>
  <joint name="left_arm_1_joint" type="revolute">
    <origin rpy="0.0 0.0 0.0" xyz="0.0 0.0 0.0"/>
    <axis xyz="0 0 1"/>
    <calibration rising="0.0"/>
    <parent link="left_arm_0_link"/>
    <child link="left_arm_1_link"/>
    <limit effort="370" lower="-3.14159265359" upper="3.14159265359" velocity="0.523598775598"/>
    <safety_controller k_position="100" k_velocity="10" soft_lower_limit="-3.10668606855" soft_upper_limit="3.10668606855"/>
  </joint>
  <link name="left_arm_1_link">
    <inertial>
      <origin rpy="0.0 0.0 0.0" xyz="0 0 -0.15875"/>
      <mass value="1.0"/>
      <inertia ixx="0.01" ixy="0" ixz="0" iyy="0.01" iyz="0" izz="0.01"/>
    </inertial>
    <visual>
      <origin rpy="0.0 0.0 0.0" xyz="0 0 -0.15875"/>
      <geometry>
        <cylinder length="0.16" radius="0.051"/>
      </geometry>
      <material name="Yellow"/>
    </visual>
    <collision>
      <origin rpy="0 0 0" xyz="0 0 -0.13875"/>
      <geometry>
        <cylinder length="0.18" radius="0.071"/>
      </geometry>
    </collision>
  </link>
  <joint name="left_arm_2_joint" type="revolute">
    <origin rpy="-1.57079632679 3.14159265359 0.0" xyz="0.0 0.0 0.0"/>
    <axis xyz="0 0 1"/>
    <calibration rising="0.0"/>
    <parent link="left_arm_1_link"/>
    <child link="left_arm_2_link"/>
    <limit effort="370" lower="-2.09439510239" upper="2.09439510239" velocity="0.523598775598"/>
    <safety_controller k_position="100" k_velocity="10" soft_lower_limit="-2.05948851735" soft_upper_limit="2.05948851735"/>
  </joint>
  <link name="left_arm_2_link">
    <inertial>
      <origin rpy="0 0 0" xyz="0 0 0"/>
      <mass value="1.0"/>
      <inertia ixx="0.01" ixy="0" ixz="0" iyy="0.01" iyz="0" izz="0.01"/>
    </inertial>
    <visual>
      <origin rpy="0 0 0" xyz="0 0 0"/>
      <geometry>
        <cylinder length="0.16" radius="0.051"/>
      </geometry>
      <material name="Black"/>
    </visual>
    <collision>
      <origin rpy="0 0 0" xyz="0 0 0"/>
      <geometry>
        <cylinder length="0.18" radius="0.071"/>
      </geometry>
    </collision>
  </link>
  <joint name="left_arm_3_joint" type="revolute">
    <origin rpy="1.57079632679 0.0 3.14159265359" xyz="0.0 0.318 0.0"/>
    <axis xyz="0 0 1"/>
    <calibration rising="0.0"/>
    <parent link="left_arm_2_link"/>
    <child link="left_arm_3_link"/>
    <limit effort="370" lower="-3.14159265359" upper="3.14159265359" velocity="0.523598775598"/>
    <safety_controller k_position="100" k_velocity="10" soft_lower_limit="-3.10668606855" soft_upper_limit="3.10668606855"/>
  </joint>
  <link name="left_arm_3_link">
    <inertial>
      <origin rpy="0 0 0" xyz="0 0 -0.159"/>
      <mass value="1.0"/>
      <inertia ixx="0.01" ixy="0" ixz="0" iyy="0.01" iyz="0" izz="0.01"/>
    </inertial>
    <visual>
      <origin rpy="0 0 0" xyz="0 0 -0.159"/>
      <geometry>
        <cylinder length="0.16" radius="0.051"/>
      </geometry>
      <material name="Yellow"/>
    </visual>
    <collision>
      <origin rpy="0 0 0" xyz="0 0 -0.159"/>
      <geometry>
        <cylinder length="0.21" radius="0.071"/>
      </geometry>
    </collision>
  </link>
  <joint name="left_arm_4_joint" type="revolute">
    <origin rpy="-1.57079632679 3.14159265359 0.0" xyz="0.0 0.0 0.0"/>
    <axis xyz="0 0 1"/>
    <calibration rising="0.0"/>
    <parent link="left_arm_3_link"/>
    <child link="left_arm_4_link"/>
    <limit effort="370" lower="-2.09439510239" upper="2.09439510239" velocity="0.523598775598"/>
    <safety_controller k_position="100" k_velocity="10" soft_lower_limit="-2.05948851735" soft_upper_limit="2.05948851735"/>
  </joint>
  <link name="left_arm_4_link">
    <inertial>
      <origin rpy="0 0 0" xyz="0 0 0"/>
      <mass value="1.0"/>
      <inertia ixx="0.01" ixy="0" ixz="0" iyy="0.01" iyz="0" izz="0.01"/>
    </inertial>
    <visual>
      <origin rpy="0 0 0" xyz="0 0 0"/>
      <geometry>
        <cylinder length="0.16" radius="0.051"/>
      </geometry>
      <material name="Black"/>
    </visual>
    <collision>
      <origin rpy="0 0 0" xyz="0 0 0"/>
      <geometry>
        <cylinder length="0.18" radius="0.071"/>
      </geometry>
    </collision>
  </link>
  <joint name="left_arm_5_joint" type="revolute">
    <origin rpy="1.57079632679 0.0 3.14159265359" xyz="0.0 0.2765 0.0"/>
    <axis xyz="0 0 1"/>
    <calibration rising="0.0"/>
    <parent link="left_arm_4_link"/>
    <child link="left_arm_5_link"/>
    <limit effort="370" lower="-3.14159265359" upper="3.14159265359" velocity="0.523598775598"/>
    <safety_controller k_position="100" k_velocity="10" soft_lower_limit="-3.10668606855" soft_upper_limit="3.10668606855"/>
  </joint>
  <link name="left_arm_5_link">
    <inertial>
      <origin rpy="0 0 0" xyz="0 0 -0.13525"/>
      <mass value="1.0"/>
      <inertia ixx="0.01" ixy="0" ixz="0" iyy="0.01" iyz="0" izz="0.01"/>
    </inertial>
    <visual>
      <origin rpy="0 0 0" xyz="0 0 -0.13525"/>
      <geometry>
        <cylinder length="0.17" radius="0.045"/>
      </geometry>
      <material name="Yellow"/>
    </visual>
    <collision>
      <origin rpy="0 0 0" xyz="0 0 -0.13525"/>
      <geometry>
        <cylinder length="0.17" radius="0.065"/>
      </geometry>
    </collision>
  </link>
  <joint name="left_arm_6_joint" type="revolute">
    <origin rpy="-1.57079632679 3.14159265359 0.0" xyz="0.0 0.0 0.0"/>
    <axis xyz="0 0 1"/>
    <calibration rising="0.0"/>
    <parent link="left_arm_5_link"/>
    <child link="left_arm_6_link"/>
    <limit effort="370" lower="-1.95476876223" upper="1.95476876223" velocity="0.523598775598"/>
    <safety_controller k_position="100" k_velocity="10" soft_lower_limit="-1.91986217719" soft_upper_limit="1.91986217719"/>
  </joint>
  <link name="left_arm_6_link">
    <inertial>
      <origin rpy="0 0 0" xyz="0 0 0"/>
      <mass value="1.0"/>
      <inertia ixx="0.01" ixy="0" ixz="0" iyy="0.01" iyz="0" izz="0.01"/>
    </inertial>
    <visual>
      <origin rpy="0 0 0" xyz="0 0 0"/>
      <geometry>
        <cylinder length="0.17" radius="0.045"/>
      </geometry>
      <material name="Black"/>
    </visual>
    <collision>
      <origin rpy="0 0 0" xyz="0 0 0"/>
      <geometry>
        <cylinder length="0.19" radius="0.065"/>
      </geometry>
    </collision>
  </link>
  <joint name="left_arm_7_joint" type="revolute">
    <origin rpy="1.57079632679 0.0 3.14159265359" xyz="0.0 0.0 0.0"/>
    <axis xyz="0 0 1"/>
    <calibration rising="0.0"/>
    <parent link="left_arm_6_link"/>
    <child link="left_arm_7_link"/>
    <limit effort="370" lower="-3.14159265359" upper="3.14159265359" velocity="0.663225115758"/>
    <safety_controller k_position="100" k_velocity="10" soft_lower_limit="-3.10668606855" soft_upper_limit="3.10668606855"/>
  </joint>
  <link name="left_arm_7_link">
    <inertial>
      <origin rpy="0 0 0" xyz="0 0 0.148424"/>
      <mass value="1.0"/>
      <inertia ixx="0.01" ixy="0" ixz="0" iyy="0.01" iyz="0" izz="0.01"/>
    </inertial>
    <visual>
      <origin rpy="0 0 0" xyz="0 0 0.148424"/>
      <geometry>
        <cylinder length="0.17" radius="0.045"/>
      </geometry>
      <material name="Yellow"/>
    </visual>
    <collision>
      <origin rpy="0 0 0" xyz="0 0 0.148424"/>
      <geometry>
        <cylinder length="0.17" radius="0.065"/>
      </geometry>
    </collision>
  </link>
  <joint name="left_arm_FT_joint" type="fixed">
    <origin rpy="0.0 0.0 0.0" xyz="0.0 0.0 0.221348"/>
    <parent link="left_arm_7_link"/>
    <child link="left_arm_FT_sensor"/>
  </joint>
  <link name="left_arm_FT_sensor">
    <inertial>
      <origin rpy="0.0 0.0 0.0" xyz="0.0 0.0 0.0"/>
      <mass value="1.0"/>
      <inertia ixx="0.01" ixy="0" ixz="0" iyy="0.01" iyz="0" izz="0.01"/>
    </inertial>
    <visual>
      <origin rpy="0.0 0.0 0.0" xyz="0.0 0.0 0.03"/>
      <geometry>
        <cylinder length="0.03" radius="0.04"/>
      </geometry>
      <material name="Grey"/>
    </visual>
    <collision>
      <origin rpy="0.0 0.0 0.0" xyz="0.0 0.0 0.03"/>
      <geometry>
        <cylinder length="0.03" radius="0.065"/>
      </geometry>
    </collision>
  </link>
  <!-- Schunk PG70 parallel gripper -->
  <joint name="left_arm_tool_joint" type="fixed">
    <origin rpy="0.0 0.0 0.0" xyz="0.0 0.0 0.414848"/>
    <parent link="left_arm_7_link"/>
    <child link="left_arm_tool_link"/>
  </joint>
  <link name="left_arm_tool_link">
    <inertial>
      <origin rpy="0 0 0" xyz="0 0 -0.1165"/>
      <mass value="1.0"/>
      <inertia ixx="0.01" ixy="0" ixz="0" iyy="0.01" iyz="0" izz="0.01"/>
    </inertial>
    <visual>
      <origin rpy="0 0 0" xyz="0 0 -0.1165"/>
      <geometry>
        <box size="0.08 0.112 0.093"/>
      </geometry>
      <material name="Black"/>
    </visual>
    <collision>
      <origin rpy="0 0 0" xyz="0 0 -0.1165"/>
      <geometry>
        <box size="0.1 0.132 0.113"/>
      </geometry>
    </collision>
  </link>
  <joint name="left_arm_top_finger_joint" type="prismatic">
    <origin rpy="0.0 0.0 0.0" xyz="0.0 0.0 -0.07"/>
    <axis xyz="0 1 0"/>
    <calibration rising="0.0"/>
    <parent link="left_arm_tool_link"/>
    <child link="left_arm_top_finger_link"/>
    <limit effort="370" lower="0.0" upper="0.03" velocity="0.01"/>
    <safety_controller k_position="100" k_velocity="10" soft_lower_limit="0.001" soft_upper_limit="0.029"/>
  </joint>
  <link name="left_arm_top_finger_link">
    <inertial>
      <origin rpy="0 0 0" xyz="0 0.01 0.035"/>
      <mass value="1.0"/>
      <inertia ixx="0.01" ixy="0" ixz="0" iyy="0.01" iyz="0" izz="0.01"/>
    </inertial>
    <visual>
      <origin rpy="0 0 0" xyz="0 0.01 0.035"/>
      <geometry>
        <box size="0.03 0.02 0.07"/>
      </geometry>
      <material name="Grey"/>
    </visual>
    <collision>
      <origin rpy="0 0 0" xyz="0 0.01 0.035"/>
      <geometry>
        <box size="0.05 0.02 0.09"/>
      </geometry>
    </collision>
  </link>
  <joint name="left_arm_bottom_finger_joint" type="prismatic">
    <origin rpy="0.0 0.0 0.0" xyz="0.0 0.0 -0.07"/>
    <axis xyz="0 -1 0"/>
    <calibration rising="0.0"/>
    <parent link="left_arm_tool_link"/>
    <child link="left_arm_bottom_finger_link"/>
    <limit effort="370" lower="0.0" upper="0.03" velocity="0.01"/>
    <safety_controller k_position="100" k_velocity="10" soft_lower_limit="0.001" soft_upper_limit="0.029"/>
  </joint>
  <link name="left_arm_bottom_finger_link">
    <inertial>
      <origin rpy="0 0 0" xyz="0 -0.01 0.035"/>
      <mass value="1.0"/>
      <inertia ixx="0.01" ixy="0" ixz="0" iyy="0.01" iyz="0" izz="0.01"/>
    </inertial>
    <visual>
      <origin rpy="0 0 0" xyz="0 -0.01 0.035"/>
      <geometry>
        <box size="0.03 0.02 0.07"/>
      </geometry>
      <material name="Grey"/>
    </visual>
    <collision>
      <origin rpy="0 0 0" xyz="0 -0.01 0.035"/>
      <geometry>
        <box size="0.05 0.02 0.09"/>
      </geometry>
    </collision>
  </link>
  <joint name="right_arm_tool_joint" type="fixed">
    <origin rpy="0.0 0.0 0.0" xyz="0.0 0.0 0.414848"/>
    <parent link="right_arm_7_link"/>
    <child link="right_arm_tool_link"/>
  </joint>
  <link name="right_arm_tool_link">
    <inertial>
      <origin rpy="0 0 0" xyz="0 0 -0.1165"/>
      <mass value="1.0"/>
      <inertia ixx="0.01" ixy="0" ixz="0" iyy="0.01" iyz="0" izz="0.01"/>
    </inertial>
    <visual>
      <origin rpy="0 0 0" xyz="0 0 -0.1165"/>
      <geometry>
        <box size="0.08 0.112 0.093"/>
      </geometry>
      <material name="Black"/>
    </visual>
    <collision>
      <origin rpy="0 0 0" xyz="0 0 -0.1165"/>
      <geometry>
        <box size="0.1 0.132 0.113"/>
      </geometry>
    </collision>
  </link>
  <joint name="right_arm_top_finger_joint" type="prismatic">
    <origin rpy="0.0 0.0 0.0" xyz="0.0 0.0 -0.07"/>
    <axis xyz="0 1 0"/>
    <calibration rising="0.0"/>
    <parent link="right_arm_tool_link"/>
    <child link="right_arm_top_finger_link"/>
    <limit effort="370" lower="0.0" upper="0.03" velocity="0.01"/>
    <safety_controller k_position="100" k_velocity="10" soft_lower_limit="0.001" soft_upper_limit="0.029"/>
  </joint>
  <link name="right_arm_top_finger_link">
    <inertial>
      <origin rpy="0 0 0" xyz="0 0.01 0.035"/>
      <mass value="1.0"/>
      <inertia ixx="0.01" ixy="0" ixz="0" iyy="0.01" iyz="0" izz="0.01"/>
    </inertial>
    <visual>
      <origin rpy="0 0 0" xyz="0 0.01 0.035"/>
      <geometry>
        <box size="0.03 0.02 0.07"/>
      </geometry>
      <material name="Grey"/>
    </visual>
    <collision>
      <origin rpy="0 0 0" xyz="0 0.01 0.035"/>
      <geometry>
        <box size="0.05 0.02 0.09"/>
      </geometry>
    </collision>
  </link>
  <joint name="right_arm_bottom_finger_joint" type="prismatic">
    <origin rpy="0.0 0.0 0.0" xyz="0.0 0.0 -0.07"/>
    <axis xyz="0 -1 0"/>
    <calibration rising="0.0"/>
    <parent link="right_arm_tool_link"/>
    <child link="right_arm_bottom_finger_link"/>
    <limit effort="370" lower="0.0" upper="0.03" velocity="0.01"/>
    <safety_controller k_position="100" k_velocity="10" soft_lower_limit="0.001" soft_upper_limit="0.029"/>
  </joint>
  <link name="right_arm_bottom_finger_link">
    <inertial>
      <origin rpy="0 0 0" xyz="0 -0.01 0.035"/>
      <mass value="1.0"/>
      <inertia ixx="0.01" ixy="0" ixz="0" iyy="0.01" iyz="0" izz="0.01"/>
    </inertial>
    <visual>
      <origin rpy="0 0 0" xyz="0 -0.01 0.035"/>
      <geometry>
        <box size="0.03 0.02 0.07"/>
      </geometry>
      <material name="Grey"/>
    </visual>
    <collision>
      <origin rpy="0 0 0" xyz="0 -0.01 0.035"/>
      <geometry>
        <box size="0.05 0.02 0.09"/>
      </geometry>
    </collision>
  </link>
</robot>
