<?xml version="1.0" ?>
<!-- =================================================================================== -->
<!-- |    This document was autogenerated by xacro from dumbo_robotiq.urdf.xacro       | -->
<!-- |    EDITING THIS FILE BY HAND IS NOT RECOMMENDED                                 | -->
<!-- =================================================================================== -->
<robot name="dumbo" xmlns:controller="http://playerstage.sourceforge.net/gazebo/xmlschema/#controller" xmlns:interface="http://playerstage.sourceforge.net/gazebo/xmlschema/#interface" xmlns:sensor="http://playerstage.sourceforge.net/gazebo/xmlschema/#sensor" xmlns:xacro="http://ros.org/wiki/xacro">
  <!-- This version incorporates Schunk PG70 parallel gripper -->
  <!-- common stuff -->
  <material name="Grey">
    <color rgba="0.7 0.7 0.7 1.0"/>
  </material>
  <material name="Grey2">
    <color rgba="0.9 0.9 0.9 1.0"/>
  </material>
  <material name="Black">
    <color rgba="0.0 0.0 0.0 1.0"/>
  </material>
  <material name="Yellow">
    <color rgba="1 1 0 1"/>
  </material>
  <material name="IPA/LightGrey">
    <color rgba="0.7 0.7 0.7 1.0"/>
  </material>
  <material name="IPA/DarkGrey">
    <color rgba="0.4 0.4 0.4 1.0"/>
  </material>
  <material name="IPA/Orange">
    <color rgba="1.0 0.4 0.0 1.0"/>
  </material>
  <material name="IPA/Black">
    <color rgba="0.0 0.0 0.0 1.0"/>
  </material>
  <material name="IPA/Blue">
    <color rgba="0.0 0.0 0.5 1.0"/>
  </material>
  <!-- The following included files set up definitions of parts of the robot body -->
  <joint name="robotiq_base_joint" type="fixed">
    <origin rpy="1.57079632679 0.0 0.0" xyz="0.0 0.0 0.33"/>
    <parent link="right_arm_7_link"/>
    <child link="robotiq_palm"/>
  </joint>
  <link name="robotiq_finger_1_link_0">
    <visual>
      <origin rpy="0 0 0" xyz="0.020 0 0"/>
      <geometry>
        <mesh filename="package://robotiq_s_model_visualization/meshes/s-model_articulated/visual/link_0.STL"/>
      </geometry>
      <material name="green">
        <color rgba="0 1 0 1"/>
      </material>
    </visual>
    <collision>
      <origin rpy="0 3.1416 -1.57" xyz="-0.0455 0.0414 0.036"/>
      <geometry>
        <mesh filename="package://robotiq_s_model_visualization/meshes/s-model_articulated/collision/link_0.STL"/>
      </geometry>
      <material name="yellow">
        <color rgba="0 1 1 1"/>
      </material>
    </collision>
  </link>
  <link name="robotiq_finger_1_link_1">
    <visual>
      <origin rpy="0 0 -0.52" xyz="0.050 -.028 0"/>
      <geometry>
        <mesh filename="package://robotiq_s_model_visualization/meshes/s-model_articulated/visual/link_1.STL"/>
      </geometry>
      <material name="green"/>
    </visual>
    <collision>
      <origin rpy="0 0 -0.52" xyz="0.050 -.028 0"/>
      <geometry>
        <mesh filename="package://robotiq_s_model_visualization/meshes/s-model_articulated/collision/link_1.STL"/>
      </geometry>
      <material name="yellow"/>
    </collision>
  </link>
  <link name="robotiq_finger_1_link_2">
    <!--
			NOTE: This link has an offset in the z-direction based on the models that were
			used to generate grap-it poses.  With the offset below the model appears visually
			correct, but it is suspect.
			-->
    <visual>
      <origin rpy="0 0 0" xyz="0.039 0 0.0075"/>
      <geometry>
        <mesh filename="package://robotiq_s_model_visualization/meshes/s-model_articulated/visual/link_2.STL"/>
      </geometry>
      <material name="green"/>
    </visual>
    <collision>
      <origin rpy="0 0 0" xyz="0.039 0 0.0075"/>
      <geometry>
        <mesh filename="package://robotiq_s_model_visualization/meshes/s-model_articulated/collision/link_2.STL"/>
      </geometry>
      <material name="yellow"/>
    </collision>
  </link>
  <link name="robotiq_finger_1_link_3">
    <visual>
      <origin rpy="0 0 0.52" xyz="0 0 0"/>
      <geometry>
        <mesh filename="package://robotiq_s_model_visualization/meshes/s-model_articulated/visual/link_3.STL"/>
      </geometry>
      <material name="green"/>
    </visual>
    <collision>
      <origin rpy="0 0 0.52" xyz="0 0 0"/>
      <geometry>
        <mesh filename="package://robotiq_s_model_visualization/meshes/s-model_articulated/collision/link_3.STL"/>
      </geometry>
      <material name="yellow"/>
    </collision>
  </link>
  <joint name="robotiq_finger_1_joint_1" type="revolute">
    <parent link="robotiq_finger_1_link_0"/>
    <child link="robotiq_finger_1_link_1"/>
    <axis xyz="0 0 1"/>
    <origin rpy="0 0 0" xyz="0.020 0 0"/>
    <limit effort="100" lower="0" upper="3.1416" velocity="100"/>
  </joint>
  <joint name="robotiq_finger_1_joint_2" type="revolute">
    <parent link="robotiq_finger_1_link_1"/>
    <child link="robotiq_finger_1_link_2"/>
    <axis xyz="0 0 1"/>
    <origin rpy="0 0 -0.52" xyz="0.050 -.028 0"/>
    <limit effort="100" lower="0" upper="3.1416" velocity="100"/>
  </joint>
  <joint name="robotiq_finger_1_joint_3" type="revolute">
    <parent link="robotiq_finger_1_link_2"/>
    <child link="robotiq_finger_1_link_3"/>
    <axis xyz="0 0 1"/>
    <origin rpy="0 0 0" xyz="0.039 0 0"/>
    <limit effort="100" lower="0" upper="3.1416" velocity="100"/>
  </joint>
  <link name="robotiq_finger_2_link_0">
    <visual>
      <origin rpy="0 0 0" xyz="0.020 0 0"/>
      <geometry>
        <mesh filename="package://robotiq_s_model_visualization/meshes/s-model_articulated/visual/link_0.STL"/>
      </geometry>
      <material name="green">
        <color rgba="0 1 0 1"/>
      </material>
    </visual>
    <collision>
      <origin rpy="0 3.1416 -1.57" xyz="-0.0455 0.0414 0.036"/>
      <geometry>
        <mesh filename="package://robotiq_s_model_visualization/meshes/s-model_articulated/collision/link_0.STL"/>
      </geometry>
      <material name="yellow">
        <color rgba="0 1 1 1"/>
      </material>
    </collision>
  </link>
  <link name="robotiq_finger_2_link_1">
    <visual>
      <origin rpy="0 0 -0.52" xyz="0.050 -.028 0"/>
      <geometry>
        <mesh filename="package://robotiq_s_model_visualization/meshes/s-model_articulated/visual/link_1.STL"/>
      </geometry>
      <material name="green"/>
    </visual>
    <collision>
      <origin rpy="0 0 -0.52" xyz="0.050 -.028 0"/>
      <geometry>
        <mesh filename="package://robotiq_s_model_visualization/meshes/s-model_articulated/collision/link_1.STL"/>
      </geometry>
      <material name="yellow"/>
    </collision>
  </link>
  <link name="robotiq_finger_2_link_2">
    <!--
			NOTE: This link has an offset in the z-direction based on the models that were
			used to generate grap-it poses.  With the offset below the model appears visually
			correct, but it is suspect.
			-->
    <visual>
      <origin rpy="0 0 0" xyz="0.039 0 0.0075"/>
      <geometry>
        <mesh filename="package://robotiq_s_model_visualization/meshes/s-model_articulated/visual/link_2.STL"/>
      </geometry>
      <material name="green"/>
    </visual>
    <collision>
      <origin rpy="0 0 0" xyz="0.039 0 0.0075"/>
      <geometry>
        <mesh filename="package://robotiq_s_model_visualization/meshes/s-model_articulated/collision/link_2.STL"/>
      </geometry>
      <material name="yellow"/>
    </collision>
  </link>
  <link name="robotiq_finger_2_link_3">
    <visual>
      <origin rpy="0 0 0.52" xyz="0 0 0"/>
      <geometry>
        <mesh filename="package://robotiq_s_model_visualization/meshes/s-model_articulated/visual/link_3.STL"/>
      </geometry>
      <material name="green"/>
    </visual>
    <collision>
      <origin rpy="0 0 0.52" xyz="0 0 0"/>
      <geometry>
        <mesh filename="package://robotiq_s_model_visualization/meshes/s-model_articulated/collision/link_3.STL"/>
      </geometry>
      <material name="yellow"/>
    </collision>
  </link>
  <joint name="robotiq_finger_2_joint_1" type="revolute">
    <parent link="robotiq_finger_2_link_0"/>
    <child link="robotiq_finger_2_link_1"/>
    <axis xyz="0 0 1"/>
    <origin rpy="0 0 0" xyz="0.020 0 0"/>
    <limit effort="100" lower="0" upper="3.1416" velocity="100"/>
  </joint>
  <joint name="robotiq_finger_2_joint_2" type="revolute">
    <parent link="robotiq_finger_2_link_1"/>
    <child link="robotiq_finger_2_link_2"/>
    <axis xyz="0 0 1"/>
    <origin rpy="0 0 -0.52" xyz="0.050 -.028 0"/>
    <limit effort="100" lower="0" upper="3.1416" velocity="100"/>
  </joint>
  <joint name="robotiq_finger_2_joint_3" type="revolute">
    <parent link="robotiq_finger_2_link_2"/>
    <child link="robotiq_finger_2_link_3"/>
    <axis xyz="0 0 1"/>
    <origin rpy="0 0 0" xyz="0.039 0 0"/>
    <limit effort="100" lower="0" upper="3.1416" velocity="100"/>
  </joint>
  <link name="robotiq_finger_middle_link_0">
    <visual>
      <origin rpy="0 0 0" xyz="0.020 0 0"/>
      <geometry>
        <mesh filename="package://robotiq_s_model_visualization/meshes/s-model_articulated/visual/link_0.STL"/>
      </geometry>
      <material name="green">
        <color rgba="0 1 0 1"/>
      </material>
    </visual>
    <collision>
      <origin rpy="0 3.1416 -1.57" xyz="-0.0455 0.0414 0.036"/>
      <geometry>
        <mesh filename="package://robotiq_s_model_visualization/meshes/s-model_articulated/collision/link_0.STL"/>
      </geometry>
      <material name="yellow">
        <color rgba="0 1 1 1"/>
      </material>
    </collision>
  </link>
  <link name="robotiq_finger_middle_link_1">
    <visual>
      <origin rpy="0 0 -0.52" xyz="0.050 -.028 0"/>
      <geometry>
        <mesh filename="package://robotiq_s_model_visualization/meshes/s-model_articulated/visual/link_1.STL"/>
      </geometry>
      <material name="green"/>
    </visual>
    <collision>
      <origin rpy="0 0 -0.52" xyz="0.050 -.028 0"/>
      <geometry>
        <mesh filename="package://robotiq_s_model_visualization/meshes/s-model_articulated/collision/link_1.STL"/>
      </geometry>
      <material name="yellow"/>
    </collision>
  </link>
  <link name="robotiq_finger_middle_link_2">
    <!--
			NOTE: This link has an offset in the z-direction based on the models that were
			used to generate grap-it poses.  With the offset below the model appears visually
			correct, but it is suspect.
			-->
    <visual>
      <origin rpy="0 0 0" xyz="0.039 0 0.0075"/>
      <geometry>
        <mesh filename="package://robotiq_s_model_visualization/meshes/s-model_articulated/visual/link_2.STL"/>
      </geometry>
      <material name="green"/>
    </visual>
    <collision>
      <origin rpy="0 0 0" xyz="0.039 0 0.0075"/>
      <geometry>
        <mesh filename="package://robotiq_s_model_visualization/meshes/s-model_articulated/collision/link_2.STL"/>
      </geometry>
      <material name="yellow"/>
    </collision>
  </link>
  <link name="robotiq_finger_middle_link_3">
    <visual>
      <origin rpy="0 0 0.52" xyz="0 0 0"/>
      <geometry>
        <mesh filename="package://robotiq_s_model_visualization/meshes/s-model_articulated/visual/link_3.STL"/>
      </geometry>
      <material name="green"/>
    </visual>
    <collision>
      <origin rpy="0 0 0.52" xyz="0 0 0"/>
      <geometry>
        <mesh filename="package://robotiq_s_model_visualization/meshes/s-model_articulated/collision/link_3.STL"/>
      </geometry>
      <material name="yellow"/>
    </collision>
  </link>
  <joint name="robotiq_finger_middle_joint_1" type="revolute">
    <parent link="robotiq_finger_middle_link_0"/>
    <child link="robotiq_finger_middle_link_1"/>
    <axis xyz="0 0 1"/>
    <origin rpy="0 0 0" xyz="0.020 0 0"/>
    <limit effort="100" lower="0" upper="3.1416" velocity="100"/>
  </joint>
  <joint name="robotiq_finger_middle_joint_2" type="revolute">
    <parent link="robotiq_finger_middle_link_1"/>
    <child link="robotiq_finger_middle_link_2"/>
    <axis xyz="0 0 1"/>
    <origin rpy="0 0 -0.52" xyz="0.050 -.028 0"/>
    <limit effort="100" lower="0" upper="3.1416" velocity="100"/>
  </joint>
  <joint name="robotiq_finger_middle_joint_3" type="revolute">
    <parent link="robotiq_finger_middle_link_2"/>
    <child link="robotiq_finger_middle_link_3"/>
    <axis xyz="0 0 1"/>
    <origin rpy="0 0 0" xyz="0.039 0 0"/>
    <limit effort="100" lower="0" upper="3.1416" velocity="100"/>
  </joint>
  <link name="robotiq_palm">
    <visual>
      <geometry>
        <mesh filename="package://robotiq_s_model_visualization/meshes/s-model_articulated/visual/palm.STL"/>
      </geometry>
      <material name="green">
        <color rgba="0 1 0 1"/>
      </material>
    </visual>
    <collision>
      <geometry>
        <mesh filename="package://robotiq_s_model_visualization/meshes/s-model_articulated/collision/palm.STL"/>
      </geometry>
      <material name="yellow">
        <color rgba="0 1 1 1"/>
      </material>
    </collision>
  </link>
  <joint name="robotiq_palm_finger_1_joint" type="revolute">
    <parent link="robotiq_palm"/>
    <child link="robotiq_finger_1_link_0"/>
    <axis xyz="0 1 0"/>
    <origin rpy="0 3.1416 -1.57" xyz="-0.0455 0.0214 0.036"/>
    <limit effort="100" lower="-0.16" upper="0.25" velocity="100"/>
  </joint>
  <joint name="robotiq_palm_finger_2_joint" type="revolute">
    <parent link="robotiq_palm"/>
    <child link="robotiq_finger_2_link_0"/>
    <axis xyz="0 1 0"/>
    <origin rpy="0 3.1416 -1.57" xyz="-0.0455 0.0214 -0.036"/>
    <limit effort="100" lower="-0.25" upper="0.16" velocity="100"/>
  </joint>
  <joint name="robotiq_palm_finger_middle_joint" type="fixed">
    <parent link="robotiq_palm"/>
    <child link="robotiq_finger_middle_link_0"/>
    <axis xyz="0 0 1"/>
    <origin rpy="0 0 1.57" xyz="0.0455 0.0214 0"/>
  </joint>
  <!-- Platform -->
  <link name="base_link">
    <!-- <inertial> -->
    <!--   <mass value="20.0" /> -->
    <!-- 	<origin xyz = "0.0 0.0 0.0" rpy="0.0 0.0 0.0" /> -->
    <!--   <inertia ixx="1.0" ixy="0.0" ixz="0.0" -->
    <!--            iyy="1.0" iyz="0.0" izz="1.0" /> -->
    <!-- </inertial> -->
    <visual>
      <origin rpy="1.57079632679 0.0 -1.57079632679" xyz="0.0 0.0 0.0"/>
      <geometry>
        <mesh filename="package://dumbo_description/meshes/platform/powerbot.ply"/>
      </geometry>
    </visual>
    <collision name="base_collision">
      <origin rpy="0.0 0.0 0.0" xyz="0.0 -0.07 0.275"/>
      <geometry>
        <box size="0.7 0.9 0.45"/>
      </geometry>
    </collision>
  </link>
  <!-- Torso -->
  <joint name="torso_joint" type="fixed">
    <origin rpy="0.0 0.0 0.0" xyz="0.0 0.06 0.696"/>
    <parent link="base_link"/>
    <child link="torso_link"/>
  </joint>
  <link name="torso_link">
    <inertial>
      <mass value="20.0"/>
      <origin rpy="0.0 0.0 0.0" xyz="0.0 0.0 0.0"/>
      <inertia ixx="3.0" ixy="0.0" ixz="0.0" iyy="3.0" iyz="0.0" izz="1.0"/>
    </inertial>
    <visual>
      <origin rpy="0.0 0.0 0.0" xyz="0.0 0.0 0.0"/>
      <geometry>
        <cylinder length="0.445" radius="0.12"/>
      </geometry>
      <material name="Black"/>
    </visual>
    <collision name="torso_collision">
      <origin rpy="0.0 0.0 0.0" xyz="0.0 0.0 0.09"/>
      <geometry>
        <box size="0.24 0.24 0.625"/>
      </geometry>
    </collision>
  </link>
  <joint name="torso_middle_plate_joint" type="fixed">
    <origin rpy="0.0 0.0 0.0" xyz="0.0 0.0 0.3125"/>
    <parent link="torso_link"/>
    <child link="torso_middle_plate_link"/>
  </joint>
  <link name="torso_middle_plate_link">
    <inertial>
      <mass value="20.0"/>
      <origin rpy="0.0 0.0 0.0" xyz="0.0 0.0 0.0"/>
      <inertia ixx="1.0" ixy="0.0" ixz="0.0" iyy="2.0" iyz="0.0" izz="0.5"/>
    </inertial>
    <visual>
      <origin rpy="0.0 0.0 0.0" xyz="0.0 0.0 0.0"/>
      <geometry>
        <box size="0.003 0.188 0.18"/>
      </geometry>
      <material name="Grey"/>
    </visual>
    <collision name="torso_middle_plate_collision">
      <origin rpy="0.0 0.0 0.0" xyz="0.0 0.0 0.0"/>
      <geometry>
        <box size="0.003 0.188 0.18"/>
      </geometry>
    </collision>
  </link>
  <joint name="torso_top_plate_joint" type="fixed">
    <origin rpy="0.0 0.0 0.0" xyz="0.0 0.0 0.0915"/>
    <parent link="torso_middle_plate_link"/>
    <child link="torso_top_plate_link"/>
  </joint>
  <link name="torso_top_plate_link">
    <inertial>
      <mass value="20.0"/>
      <origin rpy="0.0 0.0 0.0" xyz="0.0 0.0 0.0"/>
      <inertia ixx="1.0" ixy="0.0" ixz="0.0" iyy="2.0" iyz="0.0" izz="0.5"/>
    </inertial>
    <visual>
      <origin rpy="0.0 0.0 0.0" xyz="0.0 0.0 0.0"/>
      <geometry>
        <box size="0.1 0.188 0.003"/>
      </geometry>
      <material name="Black"/>
    </visual>
    <collision name="torso_top_plate_collision">
      <origin rpy="0.0 0.0 0.0" xyz="0.0 0.0 0.0"/>
      <geometry>
        <box size="0.1 0.188 0.003"/>
      </geometry>
    </collision>
  </link>
  <joint name="torso_front_plate_joint" type="fixed">
    <origin rpy="0.0 0.0 0.0" xyz="0.0 0.094 0.0"/>
    <parent link="torso_middle_plate_link"/>
    <child link="torso_front_plate_link"/>
  </joint>
  <link name="torso_front_plate_link">
    <inertial>
      <mass value="20.0"/>
      <origin rpy="0.0 0.0 0.0" xyz="0.0 0.0 0.0"/>
      <inertia ixx="1.0" ixy="0.0" ixz="0.0" iyy="2.0" iyz="0.0" izz="0.5"/>
    </inertial>
    <visual>
      <origin rpy="0.0 0.0 0.0" xyz="0.0 0.0 0.0"/>
      <geometry>
        <box size="0.1 0.003 0.18"/>
      </geometry>
      <material name="Black"/>
    </visual>
    <collision name="torso_front_plate_collision">
      <origin rpy="0.0 0.0 0.0" xyz="0.0 0.0 0.0"/>
      <geometry>
        <box size="0.1 0.003 0.18"/>
      </geometry>
    </collision>
  </link>
  <joint name="torso_back_plate_joint" type="fixed">
    <origin rpy="0.0 0.0 0.0" xyz="0.0 -0.094 0.0"/>
    <parent link="torso_middle_plate_link"/>
    <child link="torso_back_plate_link"/>
  </joint>
  <link name="torso_back_plate_link">
    <inertial>
      <mass value="20.0"/>
      <origin rpy="0.0 0.0 0.0" xyz="0.0 0.0 0.0"/>
      <inertia ixx="1.0" ixy="0.0" ixz="0.0" iyy="2.0" iyz="0.0" izz="0.5"/>
    </inertial>
    <visual>
      <origin rpy="0.0 0.0 0.0" xyz="0.0 0.0 0.0"/>
      <geometry>
        <box size="0.1 0.003 0.18"/>
      </geometry>
      <material name="Black"/>
    </visual>
    <collision name="torso_back_plate_collision">
      <origin rpy="0.0 0.0 0.0" xyz="0.0 0.0 0.0"/>
      <geometry>
        <box size="0.1 0.003 0.18"/>
      </geometry>
    </collision>
  </link>
  <joint name="arm_base_joint" type="fixed">
    <origin rpy="0.0 0.0 0.0" xyz="0.0 0.0 0.0"/>
    <parent link="torso_middle_plate_link"/>
    <child link="arm_base_link"/>
  </joint>
  <link name="arm_base_link">
    <visual>
      <origin rpy="0.0 0.0 0.0" xyz="0.0 0.0 0.0"/>
      <geometry>
        <box size="0.003 0.188 0.18"/>
      </geometry>
    </visual>
  </link>
  <!-- Accelerometer -->
  <joint name="accelerometer_joint" type="fixed">
    <origin rpy="-1.5452 -0.0353 0.0295" xyz="0.0 -0.098 0.0"/>
    <parent link="arm_base_link"/>
    <child link="accelerometer"/>
  </joint>
  <link name="accelerometer">
    <inertial>
      <origin rpy="0.0 0.0 0.0" xyz="0.0 0.0 0.0"/>
      <mass value="1.0"/>
      <inertia ixx="0.01" ixy="0" ixz="0" iyy="0.01" iyz="0" izz="0.01"/>
    </inertial>
    <visual>
      <origin rpy="0.0 0.0 0.0" xyz="0.0 0.0 0.0"/>
      <geometry>
        <box rpy="0.0 0.0 0.0" size="0.1 0.1 0.005"/>
      </geometry>
      <material name="Grey"/>
    </visual>
    <collision>
      <origin rpy="0.0 0.0 0.0" xyz="0.0 0.0 0.0"/>
      <geometry>
        <box rpy="0.0 0.0 0.0" size="0.1 0.1 0.005"/>
      </geometry>
    </collision>
  </link>
  <!-- Schunk LWA -->
  <joint name="right_arm_0_joint" type="fixed">
    <origin rpy="1.57079632679 0.0 1.57079632679" xyz="0.268 0.0 0.0"/>
    <parent link="arm_base_link"/>
    <child link="right_arm_0_link"/>
  </joint>
  <link name="right_arm_0_link">
    <inertial>
      <origin rpy="0 0 0" xyz="0 0 0"/>
      <mass value="1.0"/>
      <inertia ixx="0.01" ixy="0" ixz="0" iyy="0.01" iyz="0" izz="0.01"/>
    </inertial>
    <visual>
      <origin rpy="0 0 0" xyz="0 0 0"/>
      <geometry>
        <cylinder length="0.0001" radius="0.0001"/>
      </geometry>
    </visual>
  </link>
  <joint name="right_arm_1_joint" type="revolute">
    <origin rpy="0.0 0.0 0.0" xyz="0.0 0.0 0.0"/>
    <axis xyz="0 0 1"/>
    <calibration rising="0.0"/>
    <parent link="right_arm_0_link"/>
    <child link="right_arm_1_link"/>
    <limit effort="370" lower="-3.14159265359" upper="3.14159265359" velocity="0.523598775598"/>
    <safety_controller k_position="100" k_velocity="10" soft_lower_limit="-3.10668606855" soft_upper_limit="3.10668606855"/>
  </joint>
  <link name="right_arm_1_link">
    <inertial>
      <origin rpy="0.0 0.0 0.0" xyz="0 0 -0.15875"/>
      <mass value="1.0"/>
      <inertia ixx="0.01" ixy="0" ixz="0" iyy="0.01" iyz="0" izz="0.01"/>
    </inertial>
    <visual>
      <origin rpy="0.0 0.0 0.0" xyz="0 0 -0.15875"/>
      <geometry>
        <cylinder length="0.16" radius="0.051"/>
      </geometry>
      <material name="Yellow"/>
    </visual>
    <collision>
      <origin rpy="0 0 0" xyz="0 0 -0.13875"/>
      <geometry>
        <cylinder length="0.16" radius="0.051"/>
      </geometry>
    </collision>
  </link>
  <joint name="right_arm_2_joint" type="revolute">
    <origin rpy="-1.57079632679 3.14159265359 0.0" xyz="0.0 0.0 0.0"/>
    <axis xyz="0 0 1"/>
    <calibration rising="0.0"/>
    <parent link="right_arm_1_link"/>
    <child link="right_arm_2_link"/>
    <limit effort="370" lower="-2.09439510239" upper="2.09439510239" velocity="0.523598775598"/>
    <safety_controller k_position="100" k_velocity="10" soft_lower_limit="-2.05948851735" soft_upper_limit="2.05948851735"/>
  </joint>
  <link name="right_arm_2_link">
    <inertial>
      <origin rpy="0 0 0" xyz="0 0 0"/>
      <mass value="1.0"/>
      <inertia ixx="0.01" ixy="0" ixz="0" iyy="0.01" iyz="0" izz="0.01"/>
    </inertial>
    <visual>
      <origin rpy="0 0 0" xyz="0 0 0"/>
      <geometry>
        <cylinder length="0.16" radius="0.051"/>
      </geometry>
      <material name="Black"/>
    </visual>
    <collision>
      <origin rpy="0 0 0" xyz="0 0 0"/>
      <geometry>
        <cylinder length="0.16" radius="0.051"/>
      </geometry>
    </collision>
  </link>
  <joint name="right_arm_3_joint" type="revolute">
    <origin rpy="1.57079632679 0.0 3.14159265359" xyz="0.0 0.318 0.0"/>
    <axis xyz="0 0 1"/>
    <calibration rising="0.0"/>
    <parent link="right_arm_2_link"/>
    <child link="right_arm_3_link"/>
    <limit effort="370" lower="-3.14159265359" upper="3.14159265359" velocity="0.523598775598"/>
    <safety_controller k_position="100" k_velocity="10" soft_lower_limit="-3.10668606855" soft_upper_limit="3.10668606855"/>
  </joint>
  <link name="right_arm_3_link">
    <inertial>
      <origin rpy="0 0 0" xyz="0 0 -0.159"/>
      <mass value="1.0"/>
      <inertia ixx="0.01" ixy="0" ixz="0" iyy="0.01" iyz="0" izz="0.01"/>
    </inertial>
    <visual>
      <origin rpy="0 0 0" xyz="0 0 -0.159"/>
      <geometry>
        <cylinder length="0.16" radius="0.051"/>
      </geometry>
      <material name="Yellow"/>
    </visual>
    <collision>
      <origin rpy="0 0 0" xyz="0 0 -0.159"/>
      <geometry>
        <cylinder length="0.16" radius="0.051"/>
      </geometry>
    </collision>
  </link>
  <joint name="right_arm_4_joint" type="revolute">
    <origin rpy="-1.57079632679 3.14159265359 0.0" xyz="0.0 0.0 0.0"/>
    <axis xyz="0 0 1"/>
    <calibration rising="0.0"/>
    <parent link="right_arm_3_link"/>
    <child link="right_arm_4_link"/>
    <limit effort="370" lower="-2.09439510239" upper="2.09439510239" velocity="0.523598775598"/>
    <safety_controller k_position="100" k_velocity="10" soft_lower_limit="-2.05948851735" soft_upper_limit="2.05948851735"/>
  </joint>
  <link name="right_arm_4_link">
    <inertial>
      <origin rpy="0 0 0" xyz="0 0 0"/>
      <mass value="1.0"/>
      <inertia ixx="0.01" ixy="0" ixz="0" iyy="0.01" iyz="0" izz="0.01"/>
    </inertial>
    <visual>
      <origin rpy="0 0 0" xyz="0 0 0"/>
      <geometry>
        <cylinder length="0.16" radius="0.051"/>
      </geometry>
      <material name="Black"/>
    </visual>
    <collision>
      <origin rpy="0 0 0" xyz="0 0 0"/>
      <geometry>
        <cylinder length="0.16" radius="0.051"/>
      </geometry>
    </collision>
  </link>
  <joint name="right_arm_5_joint" type="revolute">
    <origin rpy="1.57079632679 0.0 3.14159265359" xyz="0.0 0.2765 0.0"/>
    <axis xyz="0 0 1"/>
    <calibration rising="0.0"/>
    <parent link="right_arm_4_link"/>
    <child link="right_arm_5_link"/>
    <limit effort="370" lower="-3.14159265359" upper="3.14159265359" velocity="0.523598775598"/>
    <safety_controller k_position="100" k_velocity="10" soft_lower_limit="-3.10668606855" soft_upper_limit="3.10668606855"/>
  </joint>
  <link name="right_arm_5_link">
    <inertial>
      <origin rpy="0 0 0" xyz="0 0 -0.13525"/>
      <mass value="1.0"/>
      <inertia ixx="0.01" ixy="0" ixz="0" iyy="0.01" iyz="0" izz="0.01"/>
    </inertial>
    <visual>
      <origin rpy="0 0 0" xyz="0 0 -0.13525"/>
      <geometry>
        <cylinder length="0.17" radius="0.045"/>
      </geometry>
      <material name="Yellow"/>
    </visual>
    <collision>
      <origin rpy="0 0 0" xyz="0 0 -0.13525"/>
      <geometry>
        <cylinder length="0.17" radius="0.045"/>
      </geometry>
    </collision>
  </link>
  <joint name="right_arm_6_joint" type="revolute">
    <origin rpy="-1.57079632679 3.14159265359 0.0" xyz="0.0 0.0 0.0"/>
    <axis xyz="0 0 1"/>
    <calibration rising="0.0"/>
    <parent link="right_arm_5_link"/>
    <child link="right_arm_6_link"/>
    <limit effort="370" lower="-1.95476876223" upper="1.95476876223" velocity="0.523598775598"/>
    <safety_controller k_position="100" k_velocity="10" soft_lower_limit="-1.91986217719" soft_upper_limit="1.91986217719"/>
  </joint>
  <link name="right_arm_6_link">
    <inertial>
      <origin rpy="0 0 0" xyz="0 0 0"/>
      <mass value="1.0"/>
      <inertia ixx="0.01" ixy="0" ixz="0" iyy="0.01" iyz="0" izz="0.01"/>
    </inertial>
    <visual>
      <origin rpy="0 0 0" xyz="0 0 0"/>
      <geometry>
        <cylinder length="0.17" radius="0.045"/>
      </geometry>
      <material name="Black"/>
    </visual>
    <collision>
      <origin rpy="0 0 0" xyz="0 0 0"/>
      <geometry>
        <cylinder length="0.17" radius="0.045"/>
      </geometry>
    </collision>
  </link>
  <joint name="right_arm_7_joint" type="revolute">
    <origin rpy="1.57079632679 0.0 3.14159265359" xyz="0.0 0.0 0.0"/>
    <axis xyz="0 0 1"/>
    <calibration rising="0.0"/>
    <parent link="right_arm_6_link"/>
    <child link="right_arm_7_link"/>
    <limit effort="370" lower="-3.19395253115" upper="3.19395253115" velocity="0.663225115758"/>
    <safety_controller k_position="100" k_velocity="10" soft_lower_limit="-3.15904594611" soft_upper_limit="3.15904594611"/>
  </joint>
  <link name="right_arm_7_link">
    <inertial>
      <origin rpy="0 0 0" xyz="0 0 0.148424"/>
      <mass value="1.0"/>
      <inertia ixx="0.01" ixy="0" ixz="0" iyy="0.01" iyz="0" izz="0.01"/>
    </inertial>
    <visual>
      <origin rpy="0 0 0" xyz="0 0 0.148424"/>
      <geometry>
        <cylinder length="0.17" radius="0.045"/>
      </geometry>
      <material name="Yellow"/>
    </visual>
    <collision>
      <origin rpy="0 0 0" xyz="0 0 0.148424"/>
      <geometry>
        <cylinder length="0.17" radius="0.045"/>
      </geometry>
    </collision>
  </link>
  <joint name="right_arm_ft_joint" type="fixed">
    <origin rpy="0.0 0.0 0.0" xyz="0.0 0.0 0.219848"/>
    <parent link="right_arm_7_link"/>
    <child link="right_arm_ft_sensor"/>
  </joint>
  <link name="right_arm_ft_sensor">
    <inertial>
      <origin rpy="0.0 0.0 0.0" xyz="0.0 0.0 0.0"/>
      <mass value="1.0"/>
      <inertia ixx="0.01" ixy="0" ixz="0" iyy="0.01" iyz="0" izz="0.01"/>
    </inertial>
    <visual>
      <origin rpy="0.0 0.0 0.0" xyz="0.0 0.0 0.03"/>
      <geometry>
        <cylinder length="0.03" radius="0.04"/>
      </geometry>
      <material name="Grey"/>
    </visual>
    <collision>
      <origin rpy="0.0 0.0 0.0" xyz="0.0 0.0 0.03"/>
      <geometry>
        <cylinder length="0.03" radius="0.045"/>
      </geometry>
    </collision>
  </link>
  <joint name="left_arm_0_joint" type="fixed">
    <origin rpy="1.57079632679 0.0 -1.57079632679" xyz="-0.268 0.0 0.0"/>
    <parent link="arm_base_link"/>
    <child link="left_arm_0_link"/>
  </joint>
  <link name="left_arm_0_link">
    <inertial>
      <origin rpy="0 0 0" xyz="0 0 0"/>
      <mass value="1.0"/>
      <inertia ixx="0.01" ixy="0" ixz="0" iyy="0.01" iyz="0" izz="0.01"/>
    </inertial>
    <visual>
      <origin rpy="0 0 0" xyz="0 0 0"/>
      <geometry>
        <cylinder length="0.0001" radius="0.0001"/>
      </geometry>
    </visual>
  </link>
  <joint name="left_arm_1_joint" type="revolute">
    <origin rpy="0.0 0.0 0.0" xyz="0.0 0.0 0.0"/>
    <axis xyz="0 0 1"/>
    <calibration rising="0.0"/>
    <parent link="left_arm_0_link"/>
    <child link="left_arm_1_link"/>
    <limit effort="370" lower="-3.14159265359" upper="3.14159265359" velocity="0.523598775598"/>
    <safety_controller k_position="100" k_velocity="10" soft_lower_limit="-3.10668606855" soft_upper_limit="3.10668606855"/>
  </joint>
  <link name="left_arm_1_link">
    <inertial>
      <origin rpy="0.0 0.0 0.0" xyz="0 0 -0.15875"/>
      <mass value="1.0"/>
      <inertia ixx="0.01" ixy="0" ixz="0" iyy="0.01" iyz="0" izz="0.01"/>
    </inertial>
    <visual>
      <origin rpy="0.0 0.0 0.0" xyz="0 0 -0.15875"/>
      <geometry>
        <cylinder length="0.16" radius="0.051"/>
      </geometry>
      <material name="Yellow"/>
    </visual>
    <collision>
      <origin rpy="0 0 0" xyz="0 0 -0.13875"/>
      <geometry>
        <cylinder length="0.16" radius="0.051"/>
      </geometry>
    </collision>
  </link>
  <joint name="left_arm_2_joint" type="revolute">
    <origin rpy="-1.57079632679 3.14159265359 0.0" xyz="0.0 0.0 0.0"/>
    <axis xyz="0 0 1"/>
    <calibration rising="0.0"/>
    <parent link="left_arm_1_link"/>
    <child link="left_arm_2_link"/>
    <limit effort="370" lower="-2.09439510239" upper="2.09439510239" velocity="0.523598775598"/>
    <safety_controller k_position="100" k_velocity="10" soft_lower_limit="-2.05948851735" soft_upper_limit="2.05948851735"/>
  </joint>
  <link name="left_arm_2_link">
    <inertial>
      <origin rpy="0 0 0" xyz="0 0 0"/>
      <mass value="1.0"/>
      <inertia ixx="0.01" ixy="0" ixz="0" iyy="0.01" iyz="0" izz="0.01"/>
    </inertial>
    <visual>
      <origin rpy="0 0 0" xyz="0 0 0"/>
      <geometry>
        <cylinder length="0.16" radius="0.051"/>
      </geometry>
      <material name="Black"/>
    </visual>
    <collision>
      <origin rpy="0 0 0" xyz="0 0 0"/>
      <geometry>
        <cylinder length="0.16" radius="0.051"/>
      </geometry>
    </collision>
  </link>
  <joint name="left_arm_3_joint" type="revolute">
    <origin rpy="1.57079632679 0.0 3.14159265359" xyz="0.0 0.318 0.0"/>
    <axis xyz="0 0 1"/>
    <calibration rising="0.0"/>
    <parent link="left_arm_2_link"/>
    <child link="left_arm_3_link"/>
    <limit effort="370" lower="-3.14159265359" upper="3.14159265359" velocity="0.523598775598"/>
    <safety_controller k_position="100" k_velocity="10" soft_lower_limit="-3.10668606855" soft_upper_limit="3.10668606855"/>
  </joint>
  <link name="left_arm_3_link">
    <inertial>
      <origin rpy="0 0 0" xyz="0 0 -0.159"/>
      <mass value="1.0"/>
      <inertia ixx="0.01" ixy="0" ixz="0" iyy="0.01" iyz="0" izz="0.01"/>
    </inertial>
    <visual>
      <origin rpy="0 0 0" xyz="0 0 -0.159"/>
      <geometry>
        <cylinder length="0.16" radius="0.051"/>
      </geometry>
      <material name="Yellow"/>
    </visual>
    <collision>
      <origin rpy="0 0 0" xyz="0 0 -0.159"/>
      <geometry>
        <cylinder length="0.16" radius="0.051"/>
      </geometry>
    </collision>
  </link>
  <joint name="left_arm_4_joint" type="revolute">
    <origin rpy="-1.57079632679 3.14159265359 0.0" xyz="0.0 0.0 0.0"/>
    <axis xyz="0 0 1"/>
    <calibration rising="0.0"/>
    <parent link="left_arm_3_link"/>
    <child link="left_arm_4_link"/>
    <limit effort="370" lower="-2.09439510239" upper="2.09439510239" velocity="0.523598775598"/>
    <safety_controller k_position="100" k_velocity="10" soft_lower_limit="-2.05948851735" soft_upper_limit="2.05948851735"/>
  </joint>
  <link name="left_arm_4_link">
    <inertial>
      <origin rpy="0 0 0" xyz="0 0 0"/>
      <mass value="1.0"/>
      <inertia ixx="0.01" ixy="0" ixz="0" iyy="0.01" iyz="0" izz="0.01"/>
    </inertial>
    <visual>
      <origin rpy="0 0 0" xyz="0 0 0"/>
      <geometry>
        <cylinder length="0.16" radius="0.051"/>
      </geometry>
      <material name="Black"/>
    </visual>
    <collision>
      <origin rpy="0 0 0" xyz="0 0 0"/>
      <geometry>
        <cylinder length="0.16" radius="0.051"/>
      </geometry>
    </collision>
  </link>
  <joint name="left_arm_5_joint" type="revolute">
    <origin rpy="1.57079632679 0.0 3.14159265359" xyz="0.0 0.2765 0.0"/>
    <axis xyz="0 0 1"/>
    <calibration rising="0.0"/>
    <parent link="left_arm_4_link"/>
    <child link="left_arm_5_link"/>
    <limit effort="370" lower="-3.14159265359" upper="3.14159265359" velocity="0.523598775598"/>
    <safety_controller k_position="100" k_velocity="10" soft_lower_limit="-3.10668606855" soft_upper_limit="3.10668606855"/>
  </joint>
  <link name="left_arm_5_link">
    <inertial>
      <origin rpy="0 0 0" xyz="0 0 -0.13525"/>
      <mass value="1.0"/>
      <inertia ixx="0.01" ixy="0" ixz="0" iyy="0.01" iyz="0" izz="0.01"/>
    </inertial>
    <visual>
      <origin rpy="0 0 0" xyz="0 0 -0.13525"/>
      <geometry>
        <cylinder length="0.17" radius="0.045"/>
      </geometry>
      <material name="Yellow"/>
    </visual>
    <collision>
      <origin rpy="0 0 0" xyz="0 0 -0.13525"/>
      <geometry>
        <cylinder length="0.17" radius="0.045"/>
      </geometry>
    </collision>
  </link>
  <joint name="left_arm_6_joint" type="revolute">
    <origin rpy="-1.57079632679 3.14159265359 0.0" xyz="0.0 0.0 0.0"/>
    <axis xyz="0 0 1"/>
    <calibration rising="0.0"/>
    <parent link="left_arm_5_link"/>
    <child link="left_arm_6_link"/>
    <limit effort="370" lower="-1.95476876223" upper="1.95476876223" velocity="0.523598775598"/>
    <safety_controller k_position="100" k_velocity="10" soft_lower_limit="-1.91986217719" soft_upper_limit="1.91986217719"/>
  </joint>
  <link name="left_arm_6_link">
    <inertial>
      <origin rpy="0 0 0" xyz="0 0 0"/>
      <mass value="1.0"/>
      <inertia ixx="0.01" ixy="0" ixz="0" iyy="0.01" iyz="0" izz="0.01"/>
    </inertial>
    <visual>
      <origin rpy="0 0 0" xyz="0 0 0"/>
      <geometry>
        <cylinder length="0.17" radius="0.045"/>
      </geometry>
      <material name="Black"/>
    </visual>
    <collision>
      <origin rpy="0 0 0" xyz="0 0 0"/>
      <geometry>
        <cylinder length="0.17" radius="0.045"/>
      </geometry>
    </collision>
  </link>
  <joint name="left_arm_7_joint" type="revolute">
    <origin rpy="1.57079632679 0.0 3.14159265359" xyz="0.0 0.0 0.0"/>
    <axis xyz="0 0 1"/>
    <calibration rising="0.0"/>
    <parent link="left_arm_6_link"/>
    <child link="left_arm_7_link"/>
    <limit effort="370" lower="-3.19395253115" upper="3.19395253115" velocity="0.663225115758"/>
    <safety_controller k_position="100" k_velocity="10" soft_lower_limit="-3.15904594611" soft_upper_limit="3.15904594611"/>
  </joint>
  <link name="left_arm_7_link">
    <inertial>
      <origin rpy="0 0 0" xyz="0 0 0.148424"/>
      <mass value="1.0"/>
      <inertia ixx="0.01" ixy="0" ixz="0" iyy="0.01" iyz="0" izz="0.01"/>
    </inertial>
    <visual>
      <origin rpy="0 0 0" xyz="0 0 0.148424"/>
      <geometry>
        <cylinder length="0.17" radius="0.045"/>
      </geometry>
      <material name="Yellow"/>
    </visual>
    <collision>
      <origin rpy="0 0 0" xyz="0 0 0.148424"/>
      <geometry>
        <cylinder length="0.17" radius="0.045"/>
      </geometry>
    </collision>
  </link>
  <joint name="left_arm_ft_joint" type="fixed">
    <origin rpy="0.0 0.0 0.0" xyz="0.0 0.0 0.219848"/>
    <parent link="left_arm_7_link"/>
    <child link="left_arm_ft_sensor"/>
  </joint>
  <link name="left_arm_ft_sensor">
    <inertial>
      <origin rpy="0.0 0.0 0.0" xyz="0.0 0.0 0.0"/>
      <mass value="1.0"/>
      <inertia ixx="0.01" ixy="0" ixz="0" iyy="0.01" iyz="0" izz="0.01"/>
    </inertial>
    <visual>
      <origin rpy="0.0 0.0 0.0" xyz="0.0 0.0 0.03"/>
      <geometry>
        <cylinder length="0.03" radius="0.04"/>
      </geometry>
      <material name="Grey"/>
    </visual>
    <collision>
      <origin rpy="0.0 0.0 0.0" xyz="0.0 0.0 0.03"/>
      <geometry>
        <cylinder length="0.03" radius="0.045"/>
      </geometry>
    </collision>
  </link>
  <!-- Schunk PG70 parallel gripper -->
  <joint name="left_arm_tool_joint" type="fixed">
    <origin rpy="0.0 0.0 0.0" xyz="0.0 0.0 0.414848"/>
    <parent link="left_arm_7_link"/>
    <child link="left_arm_tool_link"/>
  </joint>
  <link name="left_arm_tool_link">
    <inertial>
      <origin rpy="0 0 0" xyz="0 0 -0.1165"/>
      <mass value="1.0"/>
      <inertia ixx="0.01" ixy="0" ixz="0" iyy="0.01" iyz="0" izz="0.01"/>
    </inertial>
    <visual>
      <origin rpy="0 0 0" xyz="0 0 -0.1165"/>
      <geometry>
        <box size="0.08 0.112 0.093"/>
      </geometry>
      <material name="Black"/>
    </visual>
    <collision>
      <origin rpy="0 0 0" xyz="0 0 -0.1165"/>
      <geometry>
        <box size="0.1 0.132 0.113"/>
      </geometry>
    </collision>
  </link>
  <joint name="left_arm_top_finger_joint" type="prismatic">
    <origin rpy="0.0 0.0 0.0" xyz="0.0 0.0 -0.07"/>
    <axis xyz="0 1 0"/>
    <calibration rising="0.0"/>
    <parent link="left_arm_tool_link"/>
    <child link="left_arm_top_finger_link"/>
    <limit effort="370" lower="0.0" upper="0.03" velocity="0.01"/>
    <safety_controller k_position="100" k_velocity="10" soft_lower_limit="0.001" soft_upper_limit="0.029"/>
  </joint>
  <link name="left_arm_top_finger_link">
    <inertial>
      <origin rpy="0 0 0" xyz="0 0.01 0.035"/>
      <mass value="1.0"/>
      <inertia ixx="0.01" ixy="0" ixz="0" iyy="0.01" iyz="0" izz="0.01"/>
    </inertial>
    <visual>
      <origin rpy="0 0 0" xyz="0 0.01 0.035"/>
      <geometry>
        <box size="0.03 0.02 0.07"/>
      </geometry>
      <material name="Grey"/>
    </visual>
    <collision>
      <origin rpy="0 0 0" xyz="0 0.01 0.035"/>
      <geometry>
        <box size="0.05 0.02 0.09"/>
      </geometry>
    </collision>
  </link>
  <joint name="left_arm_bottom_finger_joint" type="prismatic">
    <origin rpy="0.0 0.0 0.0" xyz="0.0 0.0 -0.07"/>
    <axis xyz="0 -1 0"/>
    <calibration rising="0.0"/>
    <parent link="left_arm_tool_link"/>
    <child link="left_arm_bottom_finger_link"/>
    <limit effort="370" lower="0.0" upper="0.03" velocity="0.01"/>
    <safety_controller k_position="100" k_velocity="10" soft_lower_limit="0.001" soft_upper_limit="0.029"/>
  </joint>
  <link name="left_arm_bottom_finger_link">
    <inertial>
      <origin rpy="0 0 0" xyz="0 -0.01 0.035"/>
      <mass value="1.0"/>
      <inertia ixx="0.01" ixy="0" ixz="0" iyy="0.01" iyz="0" izz="0.01"/>
    </inertial>
    <visual>
      <origin rpy="0 0 0" xyz="0 -0.01 0.035"/>
      <geometry>
        <box size="0.03 0.02 0.07"/>
      </geometry>
      <material name="Grey"/>
    </visual>
    <collision>
      <origin rpy="0 0 0" xyz="0 -0.01 0.035"/>
      <geometry>
        <box size="0.05 0.02 0.09"/>
      </geometry>
    </collision>
  </link>
</robot>

