<?xml version="1.0" ?>
<!-- =================================================================================== -->
<!-- |    This document was autogenerated by xacro from dumbo_sdh.urdf.xacro           | -->
<!-- |    EDITING THIS FILE BY HAND IS NOT RECOMMENDED                                 | -->
<!-- =================================================================================== -->
<robot name="dumbo" xmlns:controller="http://playerstage.sourceforge.net/gazebo/xmlschema/#controller" xmlns:interface="http://playerstage.sourceforge.net/gazebo/xmlschema/#interface" xmlns:sensor="http://playerstage.sourceforge.net/gazebo/xmlschema/#sensor" xmlns:xacro="http://ros.org/wiki/xacro">
  <!-- This version incorporates Schunk PG70 parallel gripper -->
  <!-- common stuff -->
  <material name="Grey">
    <color rgba="0.7 0.7 0.7 1.0"/>
  </material>
  <material name="Grey2">
    <color rgba="0.9 0.9 0.9 1.0"/>
  </material>
  <material name="Black">
    <color rgba="0.0 0.0 0.0 1.0"/>
  </material>
  <material name="Yellow">
    <color rgba="1 1 0 1"/>
  </material>
  <material name="Blue">
    <color rgba="0.0 0.0 0.8 1.0"/>
  </material>
  <material name="Green">
    <color rgba="0.0 0.8 0.0 1.0"/>
  </material>
  <material name="IPA/DarkGrey">
    <color rgba="0.7 0.7 0.7 1.0"/>
  </material>
  <material name="IPA/LightGrey">
    <color rgba="0.81 0.81 0.81 1.0"/>
  </material>
  <material name="Red">
    <color rgba="0.8 0.0 0.0 1.0"/>
  </material>
  <material name="White">
    <color rgba="1.0 1.0 1.0 1.0"/>
  </material>
  <material name="IPA/Black">
    <color rgba="0.0 0.0 0.0 1.0"/>
  </material>
  <material name="IPA/Orange">
    <color rgba="1.0 0.5 0.0 1.0"/>
  </material>
  <material name="Schunk/DarkGolden">
    <color rgba="0.72 0.5255 0.043 1.0"/>
  </material>
  <material name="Caster">
    <texture filename="package://pr2_ogre/Media/materials/textures/pr2_caster_texture.png"/>
  </material>
  <material name="Wheel_l">
    <texture filename="package://pr2_ogre/Media/materials/textures/pr2_wheel_left.png"/>
  </material>
  <material name="Wheel_r">
    <texture filename="package://pr2_ogre/Media/materials/textures/pr2_wheel_right.png"/>
  </material>
  <material name="RollLinks">
    <texture filename="package://pr2_ogre/Media/materials/textures/pr2_wheel_left.png"/>
  </material>
  <!-- The following included files set up definitions of parts of the robot body -->
  <!-- Platform -->
  <link name="base_link">
    <!-- <inertial> -->
    <!--   <mass value="20.0" /> -->
    <!-- 	<origin xyz = "0.0 0.0 0.0" rpy="0.0 0.0 0.0" /> -->
    <!--   <inertia ixx="1.0" ixy="0.0" ixz="0.0" -->
    <!--            iyy="1.0" iyz="0.0" izz="1.0" /> -->
    <!-- </inertial> -->
    <visual>
      <origin rpy="1.57079632679 0.0 -1.57079632679" xyz="0.0 0.0 0.0"/>
      <geometry>
        <mesh filename="package://dumbo_description/meshes/platform/powerbot.ply"/>
      </geometry>
    </visual>
    <collision name="base_collision">
      <origin rpy="0.0 0.0 0.0" xyz="0.0 -0.07 0.275"/>
      <geometry>
        <box size="0.7 0.9 0.45"/>
      </geometry>
    </collision>
  </link>
  <!-- Torso -->
  <joint name="torso_joint" type="fixed">
    <origin rpy="0.0 0.0 0.0" xyz="0.0 0.06 0.696"/>
    <parent link="base_link"/>
    <child link="torso_link"/>
  </joint>
  <link name="torso_link">
    <inertial>
      <mass value="20.0"/>
      <origin rpy="0.0 0.0 0.0" xyz="0.0 0.0 0.0"/>
      <inertia ixx="3.0" ixy="0.0" ixz="0.0" iyy="3.0" iyz="0.0" izz="1.0"/>
    </inertial>
    <visual>
      <origin rpy="0.0 0.0 0.0" xyz="0.0 0.0 0.0"/>
      <geometry>
        <cylinder length="0.445" radius="0.12"/>
      </geometry>
      <material name="Black"/>
    </visual>
    <collision name="torso_collision">
      <origin rpy="0.0 0.0 0.0" xyz="0.0 0.0 0.09"/>
      <geometry>
        <box size="0.24 0.24 0.625"/>
      </geometry>
    </collision>
  </link>
  <joint name="torso_middle_plate_joint" type="fixed">
    <origin rpy="0.0 0.0 0.0" xyz="0.0 0.0 0.3125"/>
    <parent link="torso_link"/>
    <child link="torso_middle_plate_link"/>
  </joint>
  <link name="torso_middle_plate_link">
    <inertial>
      <mass value="20.0"/>
      <origin rpy="0.0 0.0 0.0" xyz="0.0 0.0 0.0"/>
      <inertia ixx="1.0" ixy="0.0" ixz="0.0" iyy="2.0" iyz="0.0" izz="0.5"/>
    </inertial>
    <visual>
      <origin rpy="0.0 0.0 0.0" xyz="0.0 0.0 0.0"/>
      <geometry>
        <box size="0.003 0.188 0.18"/>
      </geometry>
      <material name="Grey"/>
    </visual>
    <collision name="torso_middle_plate_collision">
      <origin rpy="0.0 0.0 0.0" xyz="0.0 0.0 0.0"/>
      <geometry>
        <box size="0.003 0.188 0.18"/>
      </geometry>
    </collision>
  </link>
  <joint name="torso_top_plate_joint" type="fixed">
    <origin rpy="0.0 0.0 0.0" xyz="0.0 0.0 0.0915"/>
    <parent link="torso_middle_plate_link"/>
    <child link="torso_top_plate_link"/>
  </joint>
  <link name="torso_top_plate_link">
    <inertial>
      <mass value="20.0"/>
      <origin rpy="0.0 0.0 0.0" xyz="0.0 0.0 0.0"/>
      <inertia ixx="1.0" ixy="0.0" ixz="0.0" iyy="2.0" iyz="0.0" izz="0.5"/>
    </inertial>
    <visual>
      <origin rpy="0.0 0.0 0.0" xyz="0.0 0.0 0.0"/>
      <geometry>
        <box size="0.1 0.188 0.003"/>
      </geometry>
      <material name="Black"/>
    </visual>
    <collision name="torso_top_plate_collision">
      <origin rpy="0.0 0.0 0.0" xyz="0.0 0.0 0.0"/>
      <geometry>
        <box size="0.1 0.188 0.003"/>
      </geometry>
    </collision>
  </link>
  <joint name="torso_front_plate_joint" type="fixed">
    <origin rpy="0.0 0.0 0.0" xyz="0.0 0.094 0.0"/>
    <parent link="torso_middle_plate_link"/>
    <child link="torso_front_plate_link"/>
  </joint>
  <link name="torso_front_plate_link">
    <inertial>
      <mass value="20.0"/>
      <origin rpy="0.0 0.0 0.0" xyz="0.0 0.0 0.0"/>
      <inertia ixx="1.0" ixy="0.0" ixz="0.0" iyy="2.0" iyz="0.0" izz="0.5"/>
    </inertial>
    <visual>
      <origin rpy="0.0 0.0 0.0" xyz="0.0 0.0 0.0"/>
      <geometry>
        <box size="0.1 0.003 0.18"/>
      </geometry>
      <material name="Black"/>
    </visual>
    <collision name="torso_front_plate_collision">
      <origin rpy="0.0 0.0 0.0" xyz="0.0 0.0 0.0"/>
      <geometry>
        <box size="0.1 0.003 0.18"/>
      </geometry>
    </collision>
  </link>
  <joint name="torso_back_plate_joint" type="fixed">
    <origin rpy="0.0 0.0 0.0" xyz="0.0 -0.094 0.0"/>
    <parent link="torso_middle_plate_link"/>
    <child link="torso_back_plate_link"/>
  </joint>
  <link name="torso_back_plate_link">
    <inertial>
      <mass value="20.0"/>
      <origin rpy="0.0 0.0 0.0" xyz="0.0 0.0 0.0"/>
      <inertia ixx="1.0" ixy="0.0" ixz="0.0" iyy="2.0" iyz="0.0" izz="0.5"/>
    </inertial>
    <visual>
      <origin rpy="0.0 0.0 0.0" xyz="0.0 0.0 0.0"/>
      <geometry>
        <box size="0.1 0.003 0.18"/>
      </geometry>
      <material name="Black"/>
    </visual>
    <collision name="torso_back_plate_collision">
      <origin rpy="0.0 0.0 0.0" xyz="0.0 0.0 0.0"/>
      <geometry>
        <box size="0.1 0.003 0.18"/>
      </geometry>
    </collision>
  </link>
  <joint name="arm_base_joint" type="fixed">
    <origin rpy="0.0 0.0 0.0" xyz="0.0 0.0 0.0"/>
    <parent link="torso_middle_plate_link"/>
    <child link="arm_base_link"/>
  </joint>
  <link name="arm_base_link">
    <visual>
      <origin rpy="0.0 0.0 0.0" xyz="0.0 0.0 0.0"/>
      <geometry>
        <box size="0.003 0.188 0.18"/>
      </geometry>
    </visual>
  </link>
  <!-- Accelerometer -->
  <joint name="accelerometer_joint" type="fixed">
    <origin rpy="-1.5452 -0.0353 0.0295" xyz="0.0 -0.098 0.0"/>
    <parent link="arm_base_link"/>
    <child link="accelerometer"/>
  </joint>
  <link name="accelerometer">
    <inertial>
      <origin rpy="0.0 0.0 0.0" xyz="0.0 0.0 0.0"/>
      <mass value="1.0"/>
      <inertia ixx="0.01" ixy="0" ixz="0" iyy="0.01" iyz="0" izz="0.01"/>
    </inertial>
    <visual>
      <origin rpy="0.0 0.0 0.0" xyz="0.0 0.0 0.0"/>
      <geometry>
        <box rpy="0.0 0.0 0.0" size="0.1 0.1 0.005"/>
      </geometry>
      <material name="Grey"/>
    </visual>
    <collision>
      <origin rpy="0.0 0.0 0.0" xyz="0.0 0.0 0.0"/>
      <geometry>
        <box rpy="0.0 0.0 0.0" size="0.1 0.1 0.005"/>
      </geometry>
    </collision>
  </link>
  <!-- Schunk LWA -->
  <joint name="right_arm_0_joint" type="fixed">
    <origin rpy="1.57079632679 0.0 1.57079632679" xyz="0.268 0.0 0.0"/>
    <parent link="arm_base_link"/>
    <child link="right_arm_0_link"/>
  </joint>
  <link name="right_arm_0_link">
    <inertial>
      <origin rpy="0 0 0" xyz="0 0 0"/>
      <mass value="1.0"/>
      <inertia ixx="0.01" ixy="0" ixz="0" iyy="0.01" iyz="0" izz="0.01"/>
    </inertial>
    <visual>
      <origin rpy="0 0 0" xyz="0 0 0"/>
      <geometry>
        <cylinder length="0.0001" radius="0.0001"/>
      </geometry>
    </visual>
  </link>
  <joint name="right_arm_1_joint" type="revolute">
    <origin rpy="0.0 0.0 0.0" xyz="0.0 0.0 0.0"/>
    <axis xyz="0 0 1"/>
    <calibration rising="0.0"/>
    <parent link="right_arm_0_link"/>
    <child link="right_arm_1_link"/>
    <limit effort="370" lower="-3.14159265359" upper="3.14159265359" velocity="0.523598775598"/>
    <safety_controller k_position="100" k_velocity="10" soft_lower_limit="-3.10668606855" soft_upper_limit="3.10668606855"/>
  </joint>
  <link name="right_arm_1_link">
    <inertial>
      <origin rpy="0.0 0.0 0.0" xyz="0 0 -0.15875"/>
      <mass value="1.0"/>
      <inertia ixx="0.01" ixy="0" ixz="0" iyy="0.01" iyz="0" izz="0.01"/>
    </inertial>
    <visual>
      <origin rpy="0.0 0.0 0.0" xyz="0 0 -0.15875"/>
      <geometry>
        <cylinder length="0.16" radius="0.051"/>
      </geometry>
      <material name="Yellow"/>
    </visual>
    <collision>
      <origin rpy="0 0 0" xyz="0 0 -0.13875"/>
      <geometry>
        <cylinder length="0.18" radius="0.071"/>
      </geometry>
    </collision>
  </link>
  <joint name="right_arm_2_joint" type="revolute">
    <origin rpy="-1.57079632679 3.14159265359 0.0" xyz="0.0 0.0 0.0"/>
    <axis xyz="0 0 1"/>
    <calibration rising="0.0"/>
    <parent link="right_arm_1_link"/>
    <child link="right_arm_2_link"/>
    <limit effort="370" lower="-2.09439510239" upper="2.09439510239" velocity="0.523598775598"/>
    <safety_controller k_position="100" k_velocity="10" soft_lower_limit="-2.05948851735" soft_upper_limit="2.05948851735"/>
  </joint>
  <link name="right_arm_2_link">
    <inertial>
      <origin rpy="0 0 0" xyz="0 0 0"/>
      <mass value="1.0"/>
      <inertia ixx="0.01" ixy="0" ixz="0" iyy="0.01" iyz="0" izz="0.01"/>
    </inertial>
    <visual>
      <origin rpy="0 0 0" xyz="0 0 0"/>
      <geometry>
        <cylinder length="0.16" radius="0.051"/>
      </geometry>
      <material name="Black"/>
    </visual>
    <collision>
      <origin rpy="0 0 0" xyz="0 0 0"/>
      <geometry>
        <cylinder length="0.18" radius="0.071"/>
      </geometry>
    </collision>
  </link>
  <joint name="right_arm_3_joint" type="revolute">
    <origin rpy="1.57079632679 0.0 3.14159265359" xyz="0.0 0.318 0.0"/>
    <axis xyz="0 0 1"/>
    <calibration rising="0.0"/>
    <parent link="right_arm_2_link"/>
    <child link="right_arm_3_link"/>
    <limit effort="370" lower="-3.14159265359" upper="3.14159265359" velocity="0.523598775598"/>
    <safety_controller k_position="100" k_velocity="10" soft_lower_limit="-3.10668606855" soft_upper_limit="3.10668606855"/>
  </joint>
  <link name="right_arm_3_link">
    <inertial>
      <origin rpy="0 0 0" xyz="0 0 -0.159"/>
      <mass value="1.0"/>
      <inertia ixx="0.01" ixy="0" ixz="0" iyy="0.01" iyz="0" izz="0.01"/>
    </inertial>
    <visual>
      <origin rpy="0 0 0" xyz="0 0 -0.159"/>
      <geometry>
        <cylinder length="0.16" radius="0.051"/>
      </geometry>
      <material name="Yellow"/>
    </visual>
    <collision>
      <origin rpy="0 0 0" xyz="0 0 -0.159"/>
      <geometry>
        <cylinder length="0.21" radius="0.071"/>
      </geometry>
    </collision>
  </link>
  <joint name="right_arm_4_joint" type="revolute">
    <origin rpy="-1.57079632679 3.14159265359 0.0" xyz="0.0 0.0 0.0"/>
    <axis xyz="0 0 1"/>
    <calibration rising="0.0"/>
    <parent link="right_arm_3_link"/>
    <child link="right_arm_4_link"/>
    <limit effort="370" lower="-2.09439510239" upper="2.09439510239" velocity="0.523598775598"/>
    <safety_controller k_position="100" k_velocity="10" soft_lower_limit="-2.05948851735" soft_upper_limit="2.05948851735"/>
  </joint>
  <link name="right_arm_4_link">
    <inertial>
      <origin rpy="0 0 0" xyz="0 0 0"/>
      <mass value="1.0"/>
      <inertia ixx="0.01" ixy="0" ixz="0" iyy="0.01" iyz="0" izz="0.01"/>
    </inertial>
    <visual>
      <origin rpy="0 0 0" xyz="0 0 0"/>
      <geometry>
        <cylinder length="0.16" radius="0.051"/>
      </geometry>
      <material name="Black"/>
    </visual>
    <collision>
      <origin rpy="0 0 0" xyz="0 0 0"/>
      <geometry>
        <cylinder length="0.18" radius="0.071"/>
      </geometry>
    </collision>
  </link>
  <joint name="right_arm_5_joint" type="revolute">
    <origin rpy="1.57079632679 0.0 3.14159265359" xyz="0.0 0.2765 0.0"/>
    <axis xyz="0 0 1"/>
    <calibration rising="0.0"/>
    <parent link="right_arm_4_link"/>
    <child link="right_arm_5_link"/>
    <limit effort="370" lower="-3.14159265359" upper="3.14159265359" velocity="0.523598775598"/>
    <safety_controller k_position="100" k_velocity="10" soft_lower_limit="-3.10668606855" soft_upper_limit="3.10668606855"/>
  </joint>
  <link name="right_arm_5_link">
    <inertial>
      <origin rpy="0 0 0" xyz="0 0 -0.13525"/>
      <mass value="1.0"/>
      <inertia ixx="0.01" ixy="0" ixz="0" iyy="0.01" iyz="0" izz="0.01"/>
    </inertial>
    <visual>
      <origin rpy="0 0 0" xyz="0 0 -0.13525"/>
      <geometry>
        <cylinder length="0.17" radius="0.045"/>
      </geometry>
      <material name="Yellow"/>
    </visual>
    <collision>
      <origin rpy="0 0 0" xyz="0 0 -0.13525"/>
      <geometry>
        <cylinder length="0.17" radius="0.065"/>
      </geometry>
    </collision>
  </link>
  <joint name="right_arm_6_joint" type="revolute">
    <origin rpy="-1.57079632679 3.14159265359 0.0" xyz="0.0 0.0 0.0"/>
    <axis xyz="0 0 1"/>
    <calibration rising="0.0"/>
    <parent link="right_arm_5_link"/>
    <child link="right_arm_6_link"/>
    <limit effort="370" lower="-1.95476876223" upper="1.95476876223" velocity="0.523598775598"/>
    <safety_controller k_position="100" k_velocity="10" soft_lower_limit="-1.91986217719" soft_upper_limit="1.91986217719"/>
  </joint>
  <link name="right_arm_6_link">
    <inertial>
      <origin rpy="0 0 0" xyz="0 0 0"/>
      <mass value="1.0"/>
      <inertia ixx="0.01" ixy="0" ixz="0" iyy="0.01" iyz="0" izz="0.01"/>
    </inertial>
    <visual>
      <origin rpy="0 0 0" xyz="0 0 0"/>
      <geometry>
        <cylinder length="0.17" radius="0.045"/>
      </geometry>
      <material name="Black"/>
    </visual>
    <collision>
      <origin rpy="0 0 0" xyz="0 0 0"/>
      <geometry>
        <cylinder length="0.19" radius="0.065"/>
      </geometry>
    </collision>
  </link>
  <joint name="right_arm_7_joint" type="revolute">
    <origin rpy="1.57079632679 0.0 3.14159265359" xyz="0.0 0.0 0.0"/>
    <axis xyz="0 0 1"/>
    <calibration rising="0.0"/>
    <parent link="right_arm_6_link"/>
    <child link="right_arm_7_link"/>
    <limit effort="370" lower="-3.19395253115" upper="3.19395253115" velocity="0.663225115758"/>
    <safety_controller k_position="100" k_velocity="10" soft_lower_limit="-3.15904594611" soft_upper_limit="3.15904594611"/>
  </joint>
  <link name="right_arm_7_link">
    <inertial>
      <origin rpy="0 0 0" xyz="0 0 0.148424"/>
      <mass value="1.0"/>
      <inertia ixx="0.01" ixy="0" ixz="0" iyy="0.01" iyz="0" izz="0.01"/>
    </inertial>
    <visual>
      <origin rpy="0 0 0" xyz="0 0 0.148424"/>
      <geometry>
        <cylinder length="0.17" radius="0.045"/>
      </geometry>
      <material name="Yellow"/>
    </visual>
    <collision>
      <origin rpy="0 0 0" xyz="0 0 0.148424"/>
      <geometry>
        <cylinder length="0.17" radius="0.065"/>
      </geometry>
    </collision>
  </link>
  <joint name="right_arm_FT_joint" type="fixed">
    <origin rpy="0.0 0.0 0.0" xyz="0.0 0.0 0.221348"/>
    <parent link="right_arm_7_link"/>
    <child link="right_arm_FT_sensor"/>
  </joint>
  <link name="right_arm_FT_sensor">
    <inertial>
      <origin rpy="0.0 0.0 0.0" xyz="0.0 0.0 0.0"/>
      <mass value="1.0"/>
      <inertia ixx="0.01" ixy="0" ixz="0" iyy="0.01" iyz="0" izz="0.01"/>
    </inertial>
    <visual>
      <origin rpy="0.0 0.0 0.0" xyz="0.0 0.0 0.03"/>
      <geometry>
        <cylinder length="0.03" radius="0.04"/>
      </geometry>
      <material name="Grey"/>
    </visual>
    <collision>
      <origin rpy="0.0 0.0 0.0" xyz="0.0 0.0 0.03"/>
      <geometry>
        <cylinder length="0.03" radius="0.065"/>
      </geometry>
    </collision>
  </link>
  <joint name="left_arm_0_joint" type="fixed">
    <origin rpy="1.57079632679 0.0 -1.57079632679" xyz="-0.268 0.0 0.0"/>
    <parent link="arm_base_link"/>
    <child link="left_arm_0_link"/>
  </joint>
  <link name="left_arm_0_link">
    <inertial>
      <origin rpy="0 0 0" xyz="0 0 0"/>
      <mass value="1.0"/>
      <inertia ixx="0.01" ixy="0" ixz="0" iyy="0.01" iyz="0" izz="0.01"/>
    </inertial>
    <visual>
      <origin rpy="0 0 0" xyz="0 0 0"/>
      <geometry>
        <cylinder length="0.0001" radius="0.0001"/>
      </geometry>
    </visual>
  </link>
  <joint name="left_arm_1_joint" type="revolute">
    <origin rpy="0.0 0.0 0.0" xyz="0.0 0.0 0.0"/>
    <axis xyz="0 0 1"/>
    <calibration rising="0.0"/>
    <parent link="left_arm_0_link"/>
    <child link="left_arm_1_link"/>
    <limit effort="370" lower="-3.14159265359" upper="3.14159265359" velocity="0.523598775598"/>
    <safety_controller k_position="100" k_velocity="10" soft_lower_limit="-3.10668606855" soft_upper_limit="3.10668606855"/>
  </joint>
  <link name="left_arm_1_link">
    <inertial>
      <origin rpy="0.0 0.0 0.0" xyz="0 0 -0.15875"/>
      <mass value="1.0"/>
      <inertia ixx="0.01" ixy="0" ixz="0" iyy="0.01" iyz="0" izz="0.01"/>
    </inertial>
    <visual>
      <origin rpy="0.0 0.0 0.0" xyz="0 0 -0.15875"/>
      <geometry>
        <cylinder length="0.16" radius="0.051"/>
      </geometry>
      <material name="Yellow"/>
    </visual>
    <collision>
      <origin rpy="0 0 0" xyz="0 0 -0.13875"/>
      <geometry>
        <cylinder length="0.18" radius="0.071"/>
      </geometry>
    </collision>
  </link>
  <joint name="left_arm_2_joint" type="revolute">
    <origin rpy="-1.57079632679 3.14159265359 0.0" xyz="0.0 0.0 0.0"/>
    <axis xyz="0 0 1"/>
    <calibration rising="0.0"/>
    <parent link="left_arm_1_link"/>
    <child link="left_arm_2_link"/>
    <limit effort="370" lower="-2.09439510239" upper="2.09439510239" velocity="0.523598775598"/>
    <safety_controller k_position="100" k_velocity="10" soft_lower_limit="-2.05948851735" soft_upper_limit="2.05948851735"/>
  </joint>
  <link name="left_arm_2_link">
    <inertial>
      <origin rpy="0 0 0" xyz="0 0 0"/>
      <mass value="1.0"/>
      <inertia ixx="0.01" ixy="0" ixz="0" iyy="0.01" iyz="0" izz="0.01"/>
    </inertial>
    <visual>
      <origin rpy="0 0 0" xyz="0 0 0"/>
      <geometry>
        <cylinder length="0.16" radius="0.051"/>
      </geometry>
      <material name="Black"/>
    </visual>
    <collision>
      <origin rpy="0 0 0" xyz="0 0 0"/>
      <geometry>
        <cylinder length="0.18" radius="0.071"/>
      </geometry>
    </collision>
  </link>
  <joint name="left_arm_3_joint" type="revolute">
    <origin rpy="1.57079632679 0.0 3.14159265359" xyz="0.0 0.318 0.0"/>
    <axis xyz="0 0 1"/>
    <calibration rising="0.0"/>
    <parent link="left_arm_2_link"/>
    <child link="left_arm_3_link"/>
    <limit effort="370" lower="-3.14159265359" upper="3.14159265359" velocity="0.523598775598"/>
    <safety_controller k_position="100" k_velocity="10" soft_lower_limit="-3.10668606855" soft_upper_limit="3.10668606855"/>
  </joint>
  <link name="left_arm_3_link">
    <inertial>
      <origin rpy="0 0 0" xyz="0 0 -0.159"/>
      <mass value="1.0"/>
      <inertia ixx="0.01" ixy="0" ixz="0" iyy="0.01" iyz="0" izz="0.01"/>
    </inertial>
    <visual>
      <origin rpy="0 0 0" xyz="0 0 -0.159"/>
      <geometry>
        <cylinder length="0.16" radius="0.051"/>
      </geometry>
      <material name="Yellow"/>
    </visual>
    <collision>
      <origin rpy="0 0 0" xyz="0 0 -0.159"/>
      <geometry>
        <cylinder length="0.21" radius="0.071"/>
      </geometry>
    </collision>
  </link>
  <joint name="left_arm_4_joint" type="revolute">
    <origin rpy="-1.57079632679 3.14159265359 0.0" xyz="0.0 0.0 0.0"/>
    <axis xyz="0 0 1"/>
    <calibration rising="0.0"/>
    <parent link="left_arm_3_link"/>
    <child link="left_arm_4_link"/>
    <limit effort="370" lower="-2.09439510239" upper="2.09439510239" velocity="0.523598775598"/>
    <safety_controller k_position="100" k_velocity="10" soft_lower_limit="-2.05948851735" soft_upper_limit="2.05948851735"/>
  </joint>
  <link name="left_arm_4_link">
    <inertial>
      <origin rpy="0 0 0" xyz="0 0 0"/>
      <mass value="1.0"/>
      <inertia ixx="0.01" ixy="0" ixz="0" iyy="0.01" iyz="0" izz="0.01"/>
    </inertial>
    <visual>
      <origin rpy="0 0 0" xyz="0 0 0"/>
      <geometry>
        <cylinder length="0.16" radius="0.051"/>
      </geometry>
      <material name="Black"/>
    </visual>
    <collision>
      <origin rpy="0 0 0" xyz="0 0 0"/>
      <geometry>
        <cylinder length="0.18" radius="0.071"/>
      </geometry>
    </collision>
  </link>
  <joint name="left_arm_5_joint" type="revolute">
    <origin rpy="1.57079632679 0.0 3.14159265359" xyz="0.0 0.2765 0.0"/>
    <axis xyz="0 0 1"/>
    <calibration rising="0.0"/>
    <parent link="left_arm_4_link"/>
    <child link="left_arm_5_link"/>
    <limit effort="370" lower="-3.14159265359" upper="3.14159265359" velocity="0.523598775598"/>
    <safety_controller k_position="100" k_velocity="10" soft_lower_limit="-3.10668606855" soft_upper_limit="3.10668606855"/>
  </joint>
  <link name="left_arm_5_link">
    <inertial>
      <origin rpy="0 0 0" xyz="0 0 -0.13525"/>
      <mass value="1.0"/>
      <inertia ixx="0.01" ixy="0" ixz="0" iyy="0.01" iyz="0" izz="0.01"/>
    </inertial>
    <visual>
      <origin rpy="0 0 0" xyz="0 0 -0.13525"/>
      <geometry>
        <cylinder length="0.17" radius="0.045"/>
      </geometry>
      <material name="Yellow"/>
    </visual>
    <collision>
      <origin rpy="0 0 0" xyz="0 0 -0.13525"/>
      <geometry>
        <cylinder length="0.17" radius="0.065"/>
      </geometry>
    </collision>
  </link>
  <joint name="left_arm_6_joint" type="revolute">
    <origin rpy="-1.57079632679 3.14159265359 0.0" xyz="0.0 0.0 0.0"/>
    <axis xyz="0 0 1"/>
    <calibration rising="0.0"/>
    <parent link="left_arm_5_link"/>
    <child link="left_arm_6_link"/>
    <limit effort="370" lower="-1.95476876223" upper="1.95476876223" velocity="0.523598775598"/>
    <safety_controller k_position="100" k_velocity="10" soft_lower_limit="-1.91986217719" soft_upper_limit="1.91986217719"/>
  </joint>
  <link name="left_arm_6_link">
    <inertial>
      <origin rpy="0 0 0" xyz="0 0 0"/>
      <mass value="1.0"/>
      <inertia ixx="0.01" ixy="0" ixz="0" iyy="0.01" iyz="0" izz="0.01"/>
    </inertial>
    <visual>
      <origin rpy="0 0 0" xyz="0 0 0"/>
      <geometry>
        <cylinder length="0.17" radius="0.045"/>
      </geometry>
      <material name="Black"/>
    </visual>
    <collision>
      <origin rpy="0 0 0" xyz="0 0 0"/>
      <geometry>
        <cylinder length="0.19" radius="0.065"/>
      </geometry>
    </collision>
  </link>
  <joint name="left_arm_7_joint" type="revolute">
    <origin rpy="1.57079632679 0.0 3.14159265359" xyz="0.0 0.0 0.0"/>
    <axis xyz="0 0 1"/>
    <calibration rising="0.0"/>
    <parent link="left_arm_6_link"/>
    <child link="left_arm_7_link"/>
    <limit effort="370" lower="-3.19395253115" upper="3.19395253115" velocity="0.663225115758"/>
    <safety_controller k_position="100" k_velocity="10" soft_lower_limit="-3.15904594611" soft_upper_limit="3.15904594611"/>
  </joint>
  <link name="left_arm_7_link">
    <inertial>
      <origin rpy="0 0 0" xyz="0 0 0.148424"/>
      <mass value="1.0"/>
      <inertia ixx="0.01" ixy="0" ixz="0" iyy="0.01" iyz="0" izz="0.01"/>
    </inertial>
    <visual>
      <origin rpy="0 0 0" xyz="0 0 0.148424"/>
      <geometry>
        <cylinder length="0.17" radius="0.045"/>
      </geometry>
      <material name="Yellow"/>
    </visual>
    <collision>
      <origin rpy="0 0 0" xyz="0 0 0.148424"/>
      <geometry>
        <cylinder length="0.17" radius="0.065"/>
      </geometry>
    </collision>
  </link>
  <joint name="left_arm_FT_joint" type="fixed">
    <origin rpy="0.0 0.0 0.0" xyz="0.0 0.0 0.221348"/>
    <parent link="left_arm_7_link"/>
    <child link="left_arm_FT_sensor"/>
  </joint>
  <link name="left_arm_FT_sensor">
    <inertial>
      <origin rpy="0.0 0.0 0.0" xyz="0.0 0.0 0.0"/>
      <mass value="1.0"/>
      <inertia ixx="0.01" ixy="0" ixz="0" iyy="0.01" iyz="0" izz="0.01"/>
    </inertial>
    <visual>
      <origin rpy="0.0 0.0 0.0" xyz="0.0 0.0 0.03"/>
      <geometry>
        <cylinder length="0.03" radius="0.04"/>
      </geometry>
      <material name="Grey"/>
    </visual>
    <collision>
      <origin rpy="0.0 0.0 0.0" xyz="0.0 0.0 0.03"/>
      <geometry>
        <cylinder length="0.03" radius="0.065"/>
      </geometry>
    </collision>
  </link>
  <!-- Schunk PG70 parallel gripper -->
  <joint name="left_arm_tool_joint" type="fixed">
    <origin rpy="0.0 0.0 0.0" xyz="0.0 0.0 0.414848"/>
    <parent link="left_arm_7_link"/>
    <child link="left_arm_tool_link"/>
  </joint>
  <link name="left_arm_tool_link">
    <inertial>
      <origin rpy="0 0 0" xyz="0 0 -0.1165"/>
      <mass value="1.0"/>
      <inertia ixx="0.01" ixy="0" ixz="0" iyy="0.01" iyz="0" izz="0.01"/>
    </inertial>
    <visual>
      <origin rpy="0 0 0" xyz="0 0 -0.1165"/>
      <geometry>
        <box size="0.08 0.112 0.093"/>
      </geometry>
      <material name="Black"/>
    </visual>
    <collision>
      <origin rpy="0 0 0" xyz="0 0 -0.1165"/>
      <geometry>
        <box size="0.1 0.132 0.113"/>
      </geometry>
    </collision>
  </link>
  <joint name="left_arm_top_finger_joint" type="prismatic">
    <origin rpy="0.0 0.0 0.0" xyz="0.0 0.0 -0.07"/>
    <axis xyz="0 1 0"/>
    <calibration rising="0.0"/>
    <parent link="left_arm_tool_link"/>
    <child link="left_arm_top_finger_link"/>
    <limit effort="370" lower="0.0" upper="0.03" velocity="0.01"/>
    <safety_controller k_position="100" k_velocity="10" soft_lower_limit="0.001" soft_upper_limit="0.029"/>
  </joint>
  <link name="left_arm_top_finger_link">
    <inertial>
      <origin rpy="0 0 0" xyz="0 0.01 0.035"/>
      <mass value="1.0"/>
      <inertia ixx="0.01" ixy="0" ixz="0" iyy="0.01" iyz="0" izz="0.01"/>
    </inertial>
    <visual>
      <origin rpy="0 0 0" xyz="0 0.01 0.035"/>
      <geometry>
        <box size="0.03 0.02 0.07"/>
      </geometry>
      <material name="Grey"/>
    </visual>
    <collision>
      <origin rpy="0 0 0" xyz="0 0.01 0.035"/>
      <geometry>
        <box size="0.05 0.02 0.09"/>
      </geometry>
    </collision>
  </link>
  <joint name="left_arm_bottom_finger_joint" type="prismatic">
    <origin rpy="0.0 0.0 0.0" xyz="0.0 0.0 -0.07"/>
    <axis xyz="0 -1 0"/>
    <calibration rising="0.0"/>
    <parent link="left_arm_tool_link"/>
    <child link="left_arm_bottom_finger_link"/>
    <limit effort="370" lower="0.0" upper="0.03" velocity="0.01"/>
    <safety_controller k_position="100" k_velocity="10" soft_lower_limit="0.001" soft_upper_limit="0.029"/>
  </joint>
  <link name="left_arm_bottom_finger_link">
    <inertial>
      <origin rpy="0 0 0" xyz="0 -0.01 0.035"/>
      <mass value="1.0"/>
      <inertia ixx="0.01" ixy="0" ixz="0" iyy="0.01" iyz="0" izz="0.01"/>
    </inertial>
    <visual>
      <origin rpy="0 0 0" xyz="0 -0.01 0.035"/>
      <geometry>
        <box size="0.03 0.02 0.07"/>
      </geometry>
      <material name="Grey"/>
    </visual>
    <collision>
      <origin rpy="0 0 0" xyz="0 -0.01 0.035"/>
      <geometry>
        <box size="0.05 0.02 0.09"/>
      </geometry>
    </collision>
  </link>
  <!-- Schunk SDH -->
  <joint name="sdh_palm_joint" type="fixed">
    <origin rpy="0.0 0.0 3.14159265359" xyz="0.0 0.0 0.251348"/>
    <parent link="right_arm_7_link"/>
    <child link="sdh_palm_link"/>
  </joint>
  <link name="sdh_palm_link">
    <inertial>
      <origin rpy="0 0 0" xyz="0 0 0"/>
      <mass value="1"/>
      <inertia ixx="0.01" ixy="0" ixz="0" iyy="0.01" iyz="0" izz="0.01"/>
    </inertial>
    <visual>
      <origin rpy="0 0 0" xyz="0 0 0"/>
      <geometry>
        <mesh filename="package://schunk_description/meshes/sdh/palm.stl"/>
      </geometry>
      <material name="IPA/DarkGrey"/>
    </visual>
    <collision>
      <origin rpy="0 0 0" xyz="0 0 0"/>
      <geometry>
        <mesh filename="package://schunk_description/meshes/sdh/palm.stl"/>
      </geometry>
    </collision>
  </link>
  <joint name="sdh_grasp_joint" type="fixed">
    <origin rpy="0 0 0" xyz="0 0 0.15"/>
    <parent link="sdh_palm_link"/>
    <child link="sdh_grasp_link"/>
  </joint>
  <link name="sdh_grasp_link"/>
  <joint name="sdh_tip_joint" type="fixed">
    <origin rpy="0 0 0" xyz="0 0 0.22"/>
    <parent link="sdh_palm_link"/>
    <child link="sdh_tip_link"/>
  </joint>
  <link name="sdh_tip_link"/>
  <joint name="sdh_knuckle_joint" type="revolute">
    <origin rpy="0 0 3.14159265" xyz="0.01905 0.033 0.0745"/>
    <parent link="sdh_palm_link"/>
    <child link="sdh_finger_11_link"/>
    <axis xyz="0 0 1"/>
    <dynamics damping="1"/>
    <limit effort="100" lower="0" upper="1.570796327" velocity="5"/>
  </joint>
  <link name="sdh_finger_11_link">
    <inertial>
      <origin rpy="0 0 0" xyz="0 0 0"/>
      <mass value="0.1"/>
      <inertia ixx="0.01" ixy="0" ixz="0" iyy="0.01" iyz="0" izz="0.01"/>
    </inertial>
    <visual>
      <origin rpy="0 0 0" xyz="0 0 0"/>
      <geometry>
        <mesh filename="package://schunk_description/meshes/sdh/knuckle.stl"/>
      </geometry>
      <material name="IPA/Black"/>
    </visual>
    <collision>
      <origin rpy="0 0 0" xyz="0 0 0"/>
      <geometry>
        <mesh filename="package://schunk_description/meshes/sdh/knuckle.stl"/>
      </geometry>
    </collision>
  </link>
  <joint name="sdh_finger_12_joint" type="revolute">
    <origin rpy="0 0 0" xyz="0 0 0.0165"/>
    <parent link="sdh_finger_11_link"/>
    <child link="sdh_finger_12_link"/>
    <axis xyz="0 1 0"/>
    <dynamics damping="1"/>
    <limit effort="100" lower="-1.570796327" upper="1.570796327" velocity="5"/>
  </joint>
  <link name="sdh_finger_12_link">
    <inertial>
      <origin rpy="0 0 0" xyz="0 0 0"/>
      <mass value="0.1"/>
      <inertia ixx="0.01" ixy="0" ixz="0" iyy="0.01" iyz="0" izz="0.01"/>
    </inertial>
    <visual>
      <origin rpy="0 0 0" xyz="0 0 0"/>
      <geometry>
        <mesh filename="package://schunk_description/meshes/sdh/finger.stl"/>
      </geometry>
      <material name="IPA/DarkGrey"/>
    </visual>
    <collision>
      <origin rpy="0 0 0" xyz="0 0 0"/>
      <geometry>
        <mesh filename="package://schunk_description/meshes/sdh/finger.stl"/>
      </geometry>
    </collision>
  </link>
  <joint name="sdh_finger_13_joint" type="revolute">
    <origin rpy="0 0 0" xyz="0 0 0.0865"/>
    <parent link="sdh_finger_12_link"/>
    <child link="sdh_finger_13_link"/>
    <axis xyz="0 1 0"/>
    <dynamics damping="1"/>
    <limit effort="100" lower="-1.570796327" upper="1.570796327" velocity="5"/>
  </joint>
  <link name="sdh_finger_13_link">
    <inertial>
      <origin rpy="0 0 0" xyz="0 0 0"/>
      <mass value="0.1"/>
      <inertia ixx="0.01" ixy="0" ixz="0" iyy="0.01" iyz="0" izz="0.01"/>
    </inertial>
    <visual>
      <origin rpy="0 0 0" xyz="0 0 0"/>
      <geometry>
        <mesh filename="package://schunk_description/meshes/sdh/finger_tip.stl"/>
      </geometry>
      <material name="IPA/Black"/>
    </visual>
    <collision>
      <origin rpy="0 0 0" xyz="0 0 0"/>
      <geometry>
        <mesh filename="package://schunk_description/meshes/sdh/finger_tip.stl"/>
      </geometry>
    </collision>
  </link>
  <joint name="sdh_finger_21_joint" type="revolute">
    <mimic joint="sdh_knuckle_joint" multiplier="1" offset="0"/>
    <origin rpy="0 0 3.14159265" xyz="0.01905 -0.033 0.0745"/>
    <parent link="sdh_palm_link"/>
    <child link="sdh_finger_21_link"/>
    <axis xyz="0 0 -1"/>
    <dynamics damping="1"/>
    <limit effort="100" lower="0" upper="1.570796327" velocity="5"/>
  </joint>
  <link name="sdh_finger_21_link">
    <inertial>
      <origin rpy="0 0 0" xyz="0 0 0"/>
      <mass value="0.1"/>
      <inertia ixx="0.01" ixy="0" ixz="0" iyy="0.01" iyz="0" izz="0.01"/>
    </inertial>
    <visual>
      <origin rpy="0 0 0" xyz="0 0 0"/>
      <geometry>
        <mesh filename="package://schunk_description/meshes/sdh/knuckle.stl"/>
      </geometry>
      <material name="IPA/Black"/>
    </visual>
    <collision>
      <origin rpy="0 0 0" xyz="0 0 0"/>
      <geometry>
        <mesh filename="package://schunk_description/meshes/sdh/knuckle.stl"/>
      </geometry>
    </collision>
  </link>
  <joint name="sdh_finger_22_joint" type="revolute">
    <origin rpy="0 0 0" xyz="0 0 0.0165"/>
    <parent link="sdh_finger_21_link"/>
    <child link="sdh_finger_22_link"/>
    <axis xyz="0 1 0"/>
    <dynamics damping="1"/>
    <limit effort="100" lower="-1.570796327" upper="1.570796327" velocity="5"/>
  </joint>
  <link name="sdh_finger_22_link">
    <inertial>
      <origin rpy="0 0 0" xyz="0 0 0"/>
      <mass value="0.1"/>
      <inertia ixx="0.01" ixy="0" ixz="0" iyy="0.01" iyz="0" izz="0.01"/>
    </inertial>
    <visual>
      <origin rpy="0 0 0" xyz="0 0 0"/>
      <geometry>
        <mesh filename="package://schunk_description/meshes/sdh/finger.stl"/>
      </geometry>
      <material name="IPA/DarkGrey"/>
    </visual>
    <collision>
      <origin rpy="0 0 0" xyz="0 0 0"/>
      <geometry>
        <mesh filename="package://schunk_description/meshes/sdh/finger.stl"/>
      </geometry>
    </collision>
  </link>
  <joint name="sdh_finger_23_joint" type="revolute">
    <origin rpy="0 0 0" xyz="0 0 0.0865"/>
    <parent link="sdh_finger_22_link"/>
    <child link="sdh_finger_23_link"/>
    <axis xyz="0 1 0"/>
    <dynamics damping="1"/>
    <limit effort="100" lower="-1.570796327" upper="1.570796327" velocity="5"/>
  </joint>
  <link name="sdh_finger_23_link">
    <inertial>
      <origin rpy="0 0 0" xyz="0 0 0"/>
      <mass value="0.1"/>
      <inertia ixx="0.01" ixy="0" ixz="0" iyy="0.01" iyz="0" izz="0.01"/>
    </inertial>
    <visual>
      <origin rpy="0 0 0" xyz="0 0 0"/>
      <geometry>
        <mesh filename="package://schunk_description/meshes/sdh/finger_tip.stl"/>
      </geometry>
      <material name="IPA/Black"/>
    </visual>
    <collision>
      <origin rpy="0 0 0" xyz="0 0 0"/>
      <geometry>
        <mesh filename="package://schunk_description/meshes/sdh/finger_tip.stl"/>
      </geometry>
    </collision>
  </link>
  <joint name="sdh_thumb_1_joint" type="fixed">
    <origin rpy="0 0 0" xyz="-0.03811 0 0.0745 "/>
    <parent link="sdh_palm_link"/>
    <child link="sdh_thumb_1_link"/>
  </joint>
  <link name="sdh_thumb_1_link">
    <inertial>
      <origin rpy="0 0 0" xyz="0 0 0"/>
      <mass value="0.1"/>
      <inertia ixx="0.01" ixy="0" ixz="0" iyy="0.01" iyz="0" izz="0.01"/>
    </inertial>
    <visual>
      <origin rpy="0 0 0" xyz="0 0 0"/>
      <geometry>
        <mesh filename="package://schunk_description/meshes/sdh/knuckle.stl"/>
      </geometry>
      <material name="IPA/Black"/>
    </visual>
    <collision>
      <origin rpy="0 0 0" xyz="0 0 0"/>
      <geometry>
        <mesh filename="package://schunk_description/meshes/sdh/knuckle.stl"/>
      </geometry>
    </collision>
  </link>
  <joint name="sdh_thumb_2_joint" type="revolute">
    <origin rpy="0 0 0" xyz="0 0 0.0165"/>
    <parent link="sdh_thumb_1_link"/>
    <child link="sdh_thumb_2_link"/>
    <axis xyz="0 1 0"/>
    <dynamics damping="1"/>
    <limit effort="100" lower="-1.570796327" upper="1.570796327" velocity="5"/>
  </joint>
  <link name="sdh_thumb_2_link">
    <inertial>
      <origin rpy="0 0 0" xyz="0 0 0"/>
      <mass value="0.1"/>
      <inertia ixx="0.01" ixy="0" ixz="0" iyy="0.01" iyz="0" izz="0.01"/>
    </inertial>
    <visual>
      <origin rpy="0 0 0" xyz="0 0 0"/>
      <geometry>
        <mesh filename="package://schunk_description/meshes/sdh/finger.stl"/>
      </geometry>
      <material name="IPA/DarkGrey"/>
    </visual>
    <collision>
      <origin rpy="0 0 0" xyz="0 0 0"/>
      <geometry>
        <mesh filename="package://schunk_description/meshes/sdh/finger.stl"/>
      </geometry>
    </collision>
  </link>
  <joint name="sdh_thumb_3_joint" type="revolute">
    <origin rpy="0 0 0" xyz="0 0 0.0865"/>
    <parent link="sdh_thumb_2_link"/>
    <child link="sdh_thumb_3_link"/>
    <axis xyz="0 1 0"/>
    <dynamics damping="1"/>
    <limit effort="100" lower="-1.570796327" upper="1.570796327" velocity="5"/>
  </joint>
  <link name="sdh_thumb_3_link">
    <inertial>
      <origin rpy="0 0 0" xyz="0 0 0"/>
      <mass value="0.1"/>
      <inertia ixx="0.01" ixy="0" ixz="0" iyy="0.01" iyz="0" izz="0.01"/>
    </inertial>
    <visual>
      <origin rpy="0 0 0" xyz="0 0 0"/>
      <geometry>
        <mesh filename="package://schunk_description/meshes/sdh/finger_tip.stl"/>
      </geometry>
      <material name="IPA/Black"/>
    </visual>
    <collision>
      <origin rpy="0 0 0" xyz="0 0 0"/>
      <geometry>
        <mesh filename="package://schunk_description/meshes/sdh/finger_tip.stl"/>
      </geometry>
    </collision>
  </link>
  <gazebo reference="sdh_palm_link">
    <material>Gazebo/Grey</material>
    <turnGravityOff>false</turnGravityOff>
  </gazebo>
  <gazebo reference="sdh_finger_11_link">
    <material>Gazebo/Black</material>
    <turnGravityOff>false</turnGravityOff>
  </gazebo>
  <gazebo reference="sdh_finger_12_link">
    <selfCollide>true</selfCollide>
    <sensor:contact name="sdh_finger_12_contact_sensor">
      <geom>sdh_finger_12_link_geom</geom>
      <updateRate>100.0</updateRate>
      <controller:gazebo_ros_bumper name="sdh_finger_12_gazebo_ros_bumper_controller" plugin="libgazebo_ros_bumper.so">
        <alwaysOn>true</alwaysOn>
        <updateRate>100.0</updateRate>
        <frameName>sdh_finger_12_link</frameName>
        <bumperTopicName>sdh_finger_12_bumper</bumperTopicName>
        <interface:bumper name="sdh_finger_12_bumper_iface"/>
      </controller:gazebo_ros_bumper>
    </sensor:contact>
    <material>IPA/Grey1</material>
    <turnGravityOff>false</turnGravityOff>
  </gazebo>
  <gazebo reference="sdh_finger_13_link">
    <selfCollide>true</selfCollide>
    <sensor:contact name="sdh_finger_13_contact_sensor">
      <geom>sdh_finger_13_link_geom</geom>
      <updateRate>100.0</updateRate>
      <controller:gazebo_ros_bumper name="sdh_finger_13_gazebo_ros_bumper_controller" plugin="libgazebo_ros_bumper.so">
        <alwaysOn>true</alwaysOn>
        <updateRate>100.0</updateRate>
        <frameName>sdh_finger_13_link</frameName>
        <bumperTopicName>sdh_finger_13_bumper</bumperTopicName>
        <interface:bumper name="sdh_finger_13_bumper_iface"/>
      </controller:gazebo_ros_bumper>
    </sensor:contact>
    <material>IPA/Grey2</material>
  </gazebo>
  <gazebo reference="sdh_finger_21_link">
    <material>Gazebo/Black</material>
    <turnGravityOff>false</turnGravityOff>
  </gazebo>
  <gazebo reference="sdh_finger_22_link">
    <selfCollide>true</selfCollide>
    <sensor:contact name="sdh_finger_22_contact_sensor">
      <geom>sdh_finger_22_link_geom</geom>
      <updateRate>100.0</updateRate>
      <controller:gazebo_ros_bumper name="sdh_finger_22_gazebo_ros_bumper_controller" plugin="libgazebo_ros_bumper.so">
        <alwaysOn>true</alwaysOn>
        <updateRate>100.0</updateRate>
        <frameName>sdh_finger_22_link</frameName>
        <bumperTopicName>sdh_finger_22_bumper</bumperTopicName>
        <interface:bumper name="sdh_finger_22_bumper_iface"/>
      </controller:gazebo_ros_bumper>
    </sensor:contact>
    <material>IPA/Grey1</material>
    <turnGravityOff>false</turnGravityOff>
  </gazebo>
  <gazebo reference="sdh_finger_23_link">
    <selfCollide>true</selfCollide>
    <sensor:contact name="sdh_finger_23_contact_sensor">
      <geom>sdh_finger_23_link_geom</geom>
      <updateRate>100.0</updateRate>
      <controller:gazebo_ros_bumper name="sdh_finger_23_gazebo_ros_bumper_controller" plugin="libgazebo_ros_bumper.so">
        <alwaysOn>true</alwaysOn>
        <updateRate>100.0</updateRate>
        <frameName>sdh_finger_23_link</frameName>
        <bumperTopicName>sdh_finger_23_bumper</bumperTopicName>
        <interface:bumper name="sdh_finger_23_bumper_iface"/>
      </controller:gazebo_ros_bumper>
    </sensor:contact>
    <material>IPA/Grey2</material>
  </gazebo>
  <gazebo reference="sdh_thumb_1_link">
    <material>Gazebo/Black</material>
    <turnGravityOff>false</turnGravityOff>
  </gazebo>
  <gazebo reference="sdh_thumb_2_link">
    <selfCollide>true</selfCollide>
    <sensor:contact name="sdh_thumb_2_contact_sensor">
      <geom>sdh_thumb_2_link_geom</geom>
      <updateRate>100.0</updateRate>
      <controller:gazebo_ros_bumper name="sdh_thumb_2_gazebo_ros_bumper_controller" plugin="libgazebo_ros_bumper.so">
        <alwaysOn>true</alwaysOn>
        <updateRate>100.0</updateRate>
        <frameName>sdh_thumb_2_link</frameName>
        <bumperTopicName>sdh_thumb_2_bumper</bumperTopicName>
        <interface:bumper name="sdh_thumb_2_bumper_iface"/>
      </controller:gazebo_ros_bumper>
    </sensor:contact>
    <material>IPA/Grey1</material>
    <turnGravityOff>false</turnGravityOff>
  </gazebo>
  <gazebo reference="sdh_thumb_3_link">
    <selfCollide>true</selfCollide>
    <sensor:contact name="sdh_thumb_3_contact_sensor">
      <geom>sdh_thumb_3_link_geom</geom>
      <updateRate>100.0</updateRate>
      <controller:gazebo_ros_bumper name="sdh_thumb_3_gazebo_ros_bumper_controller" plugin="libgazebo_ros_bumper.so">
        <alwaysOn>true</alwaysOn>
        <updateRate>100.0</updateRate>
        <frameName>sdh_thumb_3_link</frameName>
        <bumperTopicName>sdh_thumb_3_bumper</bumperTopicName>
        <interface:bumper name="sdh_thumb_3_bumper_iface"/>
      </controller:gazebo_ros_bumper>
    </sensor:contact>
    <material>IPA/Grey2</material>
  </gazebo>
  <transmission name="sdh_knuckle_trans" type="pr2_mechanism_model/SimpleTransmission">
    <actuator name="sdh_knuckle_motor"/>
    <joint name="sdh_finger_21_joint"/>
    <mechanicalReduction>1</mechanicalReduction>
  </transmission>
  <transmission name="sdh_knuckle_trans" type="pr2_mechanism_model/SimpleTransmission">
    <actuator name="sdh_knuckle_motor"/>
    <joint name="sdh_knuckle_joint"/>
    <mechanicalReduction>1</mechanicalReduction>
  </transmission>
  <transmission name="sdh_finger_12_trans" type="pr2_mechanism_model/SimpleTransmission">
    <actuator name="sdh_finger_12_motor"/>
    <joint name="sdh_finger_12_joint"/>
    <mechanicalReduction>1</mechanicalReduction>
  </transmission>
  <transmission name="sdh_finger_13_trans" type="pr2_mechanism_model/SimpleTransmission">
    <actuator name="sdh_finger_13_motor"/>
    <joint name="sdh_finger_13_joint"/>
    <mechanicalReduction>1</mechanicalReduction>
  </transmission>
  <transmission name="sdh_finger_22_trans" type="pr2_mechanism_model/SimpleTransmission">
    <actuator name="sdh_finger_22_motor"/>
    <joint name="sdh_finger_22_joint"/>
    <mechanicalReduction>1</mechanicalReduction>
  </transmission>
  <transmission name="sdh_finger_23_trans" type="pr2_mechanism_model/SimpleTransmission">
    <actuator name="sdh_finger_23_motor"/>
    <joint name="sdh_finger_23_joint"/>
    <mechanicalReduction>1</mechanicalReduction>
  </transmission>
  <transmission name="sdh_thumb_2_trans" type="pr2_mechanism_model/SimpleTransmission">
    <actuator name="sdh_thumb_2_motor"/>
    <joint name="sdh_thumb_2_joint"/>
    <mechanicalReduction>1</mechanicalReduction>
  </transmission>
  <transmission name="sdh_thumb_3_trans" type="pr2_mechanism_model/SimpleTransmission">
    <actuator name="sdh_thumb_3_motor"/>
    <joint name="sdh_thumb_3_joint"/>
    <mechanicalReduction>1</mechanicalReduction>
  </transmission>
  <!-- <xacro:dumbo_pg70_gripper name="right_arm" parent="right_arm_7_link"/> -->
</robot>
